Workbook

Sheet TEST-CASE
A1: QualityTrack — MVP · Matriz de Casos de Prueba QA para ejecución · Fases A-B-C-D · Versión 2.0 · Responsable QA: María Chiribao · Estado: Baseline validada / NOT RUN
A2: EPICS | B2: EPIC DESCRIPTION | C2: REQUERIMIENTO | D2: FEATURES | E2: FEATURE DESCRIPTION | F2: USER STORY | G2: SCENARIO | H2: ID TC | I2: ID EP | J2: ID F | K2: ID US | L2: Title | M2: Description | N2: Priority | O2: Type | P2: Pre-requisites | Q2: Test Data | R2: Acceptance Criteria | S2: Steps | T2: Expected Result | U2: Result | V2: Status | W2: Evidence | X2: Comments | Y2: Defect ID | Z2: Severity | AA2: Alineación | AB2: Fuente / PR | AC2: Clasificación QA
A3: Épica 1 — Vendedor | B3: Circuito comercial del Vendedor: registro de solicitudes y gestión de cotizaciones derivadas. | C3: FUNCIONAL | D3: Levantar pedido | E3: Levantar pedido | F3: HU-1.1 — Levantar pedido | G3: Registrar una solicitud con todos los datos obligatorios válidos | H3: TC-A-1.1-01 | I3: EP-01 | J3: F-01 | K3: HU-1.1 | L3: Registrar una solicitud con todos los datos obligatorios válidos | M3: La solicitud se registra correctamente con los datos obligatorios informados. | N3: CRITICAL | O3: FUNCTIONAL | P3: Usuario Vendedor autenticado; formulario de solicitud disponible. | Q3: Cliente nuevo con razón social, CUIT, nombre de contacto, dirección, teléfono y email válidos; descripción de pieza/trabajo válida; cantidad = 1 | R3: La solicitud se registra correctamente con los datos obligatorios informados. | S3: 1. Ingresar los datos del cliente. 2. Ingresar descripción. 3. Informar cantidad. 4. Guardar solicitud. | T3: La solicitud se registra correctamente con los datos obligatorios informados. | U3: PASS | V3: PASS | W3: TC-A-1.1-01 | X3: Modificado: Los datos del cliente nuevo incluyen CUIT, contacto y email, todos obligatorios. (ref. D-4) | AA3: OFICIAL / BASELINE | AB3: PRD V2 + Backlog V2 + DB V2 + QA | AC3: Caso del alcance
A4: Épica 1 — Vendedor | B4: Circuito comercial del Vendedor: registro de solicitudes y gestión de cotizaciones derivadas. | C4: FUNCIONAL | D4: Levantar pedido | E4: Levantar pedido | F4: HU-1.1 — Levantar pedido | G4: Registrar solicitud sin razón social | H4: TC-A-1.1-02 | I4: EP-01 | J4: F-01 | K4: HU-1.1 | L4: Registrar solicitud sin razón social | M4: La solicitud no debe registrarse porque la razón social es obligatoria. | N4: HIGH | O4: NEGATIVE | P4: Usuario Vendedor autenticado; formulario de solicitud disponible. | Q4: Dirección y teléfono válidos; descripción válida; cantidad = 1; razón social vacía | R4: La solicitud no debe registrarse porque la razón social es obligatoria. | S4: 1. Completar los campos restantes. 2. Dejar razón social vacía. 3. Intentar guardar. | T4: La solicitud no debe registrarse porque la razón social es obligatoria. | U4: PASS | V4: PASS | W4: TC-A-1.1-02 | AA4: OFICIAL / BASELINE | AB4: PRD V2 + Backlog V2 + DB V2 + QA | AC4: Caso del alcance
A5: Épica 1 — Vendedor | B5: Circuito comercial del Vendedor: registro de solicitudes y gestión de cotizaciones derivadas. | C5: FUNCIONAL | D5: Levantar pedido | E5: Levantar pedido | F5: HU-1.1 — Levantar pedido | G5: Registrar cliente nuevo sin dirección | H5: TC-A-1.1-03 | I5: EP-01 | J5: F-01 | K5: HU-1.1 | L5: Registrar cliente nuevo sin dirección | M5: La solicitud no se registra y el sistema señala que falta la dirección, que es obligatoria. | N5: MEDIUM | O5: NEGATIVE | P5: Usuario Vendedor autenticado; formulario de solicitud disponible. | Q5: Razón social, CUIT, contacto, teléfono y email válidos; descripción válida; cantidad = 1; dirección vacía | R5: La solicitud no se registra y el sistema señala que falta la dirección, que es obligatoria. | S5: 1. Completar los campos restantes. 2. Dejar dirección vacía. 3. Intentar guardar. | T5: La solicitud no se registra y el sistema señala que falta la dirección, que es obligatoria. | U5: PASS | V5: PASS | W5: TC-A-1.1-03 | X5: Modificado: Sin dirección, la solicitud no se registra. (ref. D-4) | AA5: OFICIAL / BASELINE | AB5: PRD V2 + Backlog V2 + DB V2 + QA | AC5: Caso del alcance
A6: Épica 1 — Vendedor | B6: Circuito comercial del Vendedor: registro de solicitudes y gestión de cotizaciones derivadas. | C6: FUNCIONAL | D6: Levantar pedido | E6: Levantar pedido | F6: HU-1.1 — Levantar pedido | G6: Registrar cliente nuevo sin teléfono | H6: TC-A-1.1-04 | I6: EP-01 | J6: F-01 | K6: HU-1.1 | L6: Registrar cliente nuevo sin teléfono | M6: La solicitud no se registra y el sistema señala que falta el teléfono, que es obligatorio. | N6: MEDIUM | O6: NEGATIVE | P6: Usuario Vendedor autenticado; formulario de solicitud disponible. | Q6: Razón social, CUIT, contacto, dirección y email válidos; descripción válida; cantidad = 1; teléfono vacío | R6: La solicitud no se registra y el sistema señala que falta el teléfono, que es obligatorio. | S6: 1. Completar los campos restantes. 2. Dejar teléfono vacío. 3. Intentar guardar. | T6: La solicitud no se registra y el sistema señala que falta el teléfono, que es obligatorio. | U6: PASS | V6: PASS | W6: TC-A-1.1-04 | X6: Modificado: Sin teléfono, la solicitud no se registra. (ref. D-4) | AA6: OFICIAL / BASELINE | AB6: PRD V2 + Backlog V2 + DB V2 + QA | AC6: Caso del alcance
A7: Épica 1 — Vendedor | B7: Circuito comercial del Vendedor: registro de solicitudes y gestión de cotizaciones derivadas. | C7: FUNCIONAL | D7: Levantar pedido | E7: Levantar pedido | F7: HU-1.1 — Levantar pedido | G7: Registrar solicitud sin descripción de pieza/trabajo | H7: TC-A-1.1-05 | I7: EP-01 | J7: F-01 | K7: HU-1.1 | L7: Registrar solicitud sin descripción de pieza/trabajo | M7: La solicitud no debe registrarse porque la descripción de pieza/trabajo es obligatoria. | N7: CRITICAL | O7: NEGATIVE | P7: Usuario Vendedor autenticado; formulario de solicitud disponible. | Q7: Datos del cliente válidos; descripción vacía; cantidad = 1 | R7: La solicitud no debe registrarse porque la descripción de pieza/trabajo es obligatoria. | S7: 1. Completar los datos del cliente. 2. Dejar descripción vacía. 3. Informar cantidad. 4. Intentar guardar. | T7: La solicitud no debe registrarse porque la descripción de pieza/trabajo es obligatoria. | U7: PASS | V7: PASS | W7: TC-A-1.1-05 | AA7: OFICIAL / BASELINE | AB7: PRD V2 + Backlog V2 + DB V2 + QA | AC7: Caso del alcance
A8: Épica 1 — Vendedor | B8: Circuito comercial del Vendedor: registro de solicitudes y gestión de cotizaciones derivadas. | C8: FUNCIONAL | D8: Levantar pedido | E8: Levantar pedido | F8: HU-1.1 — Levantar pedido | G8: Registrar solicitud sin cantidad | H8: TC-A-1.1-06 | I8: EP-01 | J8: F-01 | K8: HU-1.1 | L8: Registrar solicitud sin cantidad | M8: La solicitud no debe registrarse porque la cantidad es obligatoria. | N8: CRITICAL | O8: NEGATIVE | P8: Usuario Vendedor autenticado; formulario de solicitud disponible. | Q8: Datos del cliente válidos; descripción válida; cantidad no informada | R8: La solicitud no debe registrarse porque la cantidad es obligatoria. | S8: 1. Completar los datos obligatorios del cliente. 2. Informar descripción. 3. No informar cantidad. 4. Intentar guardar. | T8: La solicitud no debe registrarse porque la cantidad es obligatoria. | U8: PASS | V8: PASS | W8: TC-A-1.1-06 | AA8: OFICIAL / BASELINE | AB8: PRD V2 + Backlog V2 + DB V2 + QA | AC8: Caso del alcance
A9: Épica 1 — Vendedor | B9: Circuito comercial del Vendedor: registro de solicitudes y gestión de cotizaciones derivadas. | C9: FUNCIONAL | D9: Levantar pedido | E9: Levantar pedido | F9: HU-1.1 — Levantar pedido | G9: Registrar solicitud con cantidad igual a 0 | H9: TC-A-1.1-07 | I9: EP-01 | J9: F-01 | K9: HU-1.1 | L9: Registrar solicitud con cantidad igual a 0 | M9: La solicitud no debe registrarse porque la cantidad debe ser mayor que 0. | N9: HIGH | O9: NEGATIVE | P9: Usuario Vendedor autenticado; formulario de solicitud disponible. | Q9: Datos del cliente válidos; descripción válida; cantidad = 0 | R9: La solicitud no debe registrarse porque la cantidad debe ser mayor que 0. | S9: 1. Completar los datos obligatorios. 2. Informar cantidad = 0. 3. Intentar guardar. | T9: La solicitud no debe registrarse porque la cantidad debe ser mayor que 0. | U9: PASS | V9: PASS | W9: TC-A-1.1-07 | AA9: OFICIAL / BASELINE | AB9: PRD V2 + Backlog V2 + DB V2 + QA | AC9: Caso del alcance
A10: Épica 1 — Vendedor | B10: Circuito comercial del Vendedor: registro de solicitudes y gestión de cotizaciones derivadas. | C10: FUNCIONAL | D10: Levantar pedido | E10: Levantar pedido | F10: HU-1.1 — Levantar pedido | G10: Registrar solicitud con cantidad negativa | H10: TC-A-1.1-08 | I10: EP-01 | J10: F-01 | K10: HU-1.1 | L10: Registrar solicitud con cantidad negativa | M10: La solicitud no debe registrarse porque la cantidad debe ser mayor que 0. | N10: HIGH | O10: NEGATIVE | P10: Usuario Vendedor autenticado; formulario de solicitud disponible. | Q10: Datos del cliente válidos; descripción válida; cantidad < 0 | R10: La solicitud no debe registrarse porque la cantidad debe ser mayor que 0. | S10: 1. Completar los datos obligatorios. 2. Informar una cantidad negativa. 3. Intentar guardar. | T10: La solicitud no debe registrarse porque la cantidad debe ser mayor que 0. | U10: PASS | V10: PASS | W10: TC-A-1.1-08 | AA10: OFICIAL / BASELINE | AB10: PRD V2 + Backlog V2 + DB V2 + QA | AC10: Caso del alcance
A11: Épica 1 — Vendedor | B11: Circuito comercial del Vendedor: registro de solicitudes y gestión de cotizaciones derivadas. | C11: FUNCIONAL | D11: Levantar pedido | E11: Levantar pedido | F11: HU-1.1 — Levantar pedido | G11: Registrar solicitud con cantidad válida mayor que 0 | H11: TC-A-1.1-09 | I11: EP-01 | J11: F-01 | K11: HU-1.1 | L11: Registrar solicitud con cantidad válida mayor que 0 | M11: La solicitud se registra correctamente con la cantidad informada. | N11: HIGH | O11: FUNCTIONAL | P11: Usuario Vendedor autenticado; formulario de solicitud disponible. | Q11: Datos del cliente válidos; descripción válida; cantidad > 0 | R11: La solicitud se registra correctamente con la cantidad informada. | S11: 1. Completar los datos obligatorios. 2. Informar una cantidad mayor que 0. 3. Guardar. | T11: La solicitud se registra correctamente con la cantidad informada. | U11: PASS | V11: PASS | W11: TC-A-1.1-09 | AA11: OFICIAL / BASELINE | AB11: PRD V2 + Backlog V2 + DB V2 + QA | AC11: Caso del alcance
A12: Épica 1 — Vendedor | B12: Circuito comercial del Vendedor: registro de solicitudes y gestión de cotizaciones derivadas. | C12: FUNCIONAL | D12: Levantar pedido | E12: Levantar pedido | F12: HU-1.1 — Levantar pedido | G12: Verificar estado inicial de la solicitud | H12: TC-A-1.1-10 | I12: EP-01 | J12: F-01 | K12: HU-1.1 | L12: Verificar estado inicial de la solicitud | M12: La solicitud queda registrada con estado PENDIENTE_COTIZACION. | N12: CRITICAL | O12: FUNCTIONAL | P12: Usuario Vendedor autenticado; formulario de solicitud disponible. | Q12: Solicitud creada con todos los datos obligatorios válidos | R12: La solicitud queda registrada con estado PENDIENTE_COTIZACION. | S12: 1. Registrar la solicitud. 2. Consultar su estado. | T12: La solicitud queda registrada con estado PENDIENTE_COTIZACION. | U12: PASS | V12: PASS | W12: TC-A-1.1-10 | X12: pendiente de cotizacion | AA12: OFICIAL / BASELINE | AB12: PRD V2 + Backlog V2 + DB V2 + QA | AC12: Caso del alcance
A13: Épica 1 — Vendedor | B13: Circuito comercial del Vendedor: registro de solicitudes y gestión de cotizaciones derivadas. | C13: FUNCIONAL | D13: Levantar pedido | E13: Levantar pedido | F13: HU-1.1 — Levantar pedido | G13: Verificar persistencia de los datos registrados | H13: TC-A-1.1-11 | I13: EP-01 | J13: F-01 | K13: HU-1.1 | L13: Verificar persistencia de los datos registrados | M13: Los datos registrados permanecen disponibles y consistentes después de la creación. | N13: HIGH | O13: INTEGRATION | P13: Usuario Vendedor autenticado; formulario de solicitud disponible. | Q13: Solicitud válida con datos completos | R13: Los datos registrados permanecen disponibles y consistentes después de la creación. | S13: 1. Registrar solicitud. 2. Consultar posteriormente la solicitud. 3. Comparar los datos registrados. | T13: Los datos registrados permanecen disponibles y consistentes después de la creación. | U13: PASS | V13: PASS | W13: TC-A-1.1-11 | AA13: OFICIAL / BASELINE | AB13: PRD V2 + Backlog V2 + DB V2 + QA | AC13: Caso del alcance
A14: Épica 1 — Vendedor | B14: Circuito comercial del Vendedor: registro de solicitudes y gestión de cotizaciones derivadas. | C14: FUNCIONAL | D14: Levantar pedido | E14: Levantar pedido | F14: HU-1.1 — Levantar pedido | G14: Registrar solicitud con cliente ya registrado | H14: TC-A-1.1-12 | I14: EP-01 | J14: F-01 | K14: HU-1.1 | L14: Registrar solicitud con cliente ya registrado | M14: La solicitud se registra correctamente asociada al cliente existente mediante su cliente_id. | N14: CRITICAL | O14: INTEGRATION | P14: Usuario Vendedor autenticado; formulario de solicitud disponible. | Q14: cliente_id válido correspondiente a un cliente existente; descripción válida; cantidad = 1 | R14: La solicitud se registra correctamente asociada al cliente existente mediante su cliente_id. | S14: 1. Seleccionar un cliente ya registrado. 2. Verificar que se utilice su cliente_id. 3. Completar la solicitud. 4. Guardar. | T14: La solicitud se registra correctamente asociada al cliente existente mediante su cliente_id. | U14: PASS | V14: PASS | W14: TC-A-1.1-12 | AA14: OFICIAL / BASELINE | AB14: PRD V2 + Backlog V2 + DB V2 + QA | AC14: Caso del alcance
A15: Épica 1 — Vendedor | B15: Circuito comercial del Vendedor: registro de solicitudes y gestión de cotizaciones derivadas. | C15: FUNCIONAL | D15: Levantar pedido | E15: Levantar pedido | F15: HU-1.1 — Levantar pedido | G15: Registrar solicitud con cliente_id inexistente | H15: TC-A-1.1-13 | I15: EP-01 | J15: F-01 | K15: HU-1.1 | L15: Registrar solicitud con cliente_id inexistente | M15: La solicitud no debe registrarse y el sistema debe rechazar la referencia a un cliente inexistente. | N15: HIGH | O15: NEGATIVE | P15: Usuario Vendedor autenticado; formulario de solicitud disponible. | Q15: cliente_id inexistente; descripción válida; cantidad = 1 | R15: La solicitud no debe registrarse y el sistema debe rechazar la referencia a un cliente inexistente. | S15: 1. Informar un cliente_id inexistente. 2. Completar los datos restantes. 3. Intentar guardar. | T15: La solicitud no debe registrarse y el sistema debe rechazar la referencia a un cliente inexistente. | U15: PASS | V15: PASS | W15: TC-A-1.1-13 | AA15: OFICIAL / BASELINE | AB15: PRD V2 + Backlog V2 + DB V2 + QA | AC15: Caso del alcance
A16: Épica 1 — Vendedor | B16: Circuito comercial del Vendedor: registro de solicitudes y gestión de cotizaciones derivadas. | C16: FUNCIONAL | D16: Levantar pedido | E16: Levantar pedido | F16: HU-1.1 — Levantar pedido | G16: Adjuntar documentación válida a la solicitud | H16: TC-A-1.1-14 | I16: EP-01 | J16: F-01 | K16: HU-1.1 | L16: Adjuntar documentación válida a la solicitud | M16: La documentación se adjunta correctamente, sigue disponible al recargar y se puede abrir desde el navegador sin descargarla. | N16: HIGH | O16: FUNCTIONAL | P16: Usuario Vendedor autenticado; formulario de solicitud disponible. | Q16: Archivo de hasta 10 MB, por ejemplo un plano | R16: La documentación se adjunta correctamente, sigue disponible al recargar y se puede abrir desde el navegador sin descargarla. | S16: 1. Completar la solicitud. 2. Adjuntar el plano. 3. Guardar. 4. Recargar la solicitud. 5. Abrir el documento. | T16: La documentación se adjunta correctamente, sigue disponible al recargar y se puede abrir desde el navegador sin descargarla. | U16: FAIL | V16: FAIL | W16: TC-A-1.1-14 | X16: Modificado: El adjunto sigue disponible al recargar y se abre desde el navegador. (ref. D-6) Prueba exploratoria de seguridad | Z16: CRITICAL | AA16: OFICIAL / BASELINE | AB16: PRD V2 + Backlog V2 + DB V2 + QA | AC16: Caso del alcance
A17: Épica 1 — Vendedor | B17: Circuito comercial del Vendedor: registro de solicitudes y gestión de cotizaciones derivadas. | C17: FUNCIONAL | D17: Levantar pedido | E17: Levantar pedido | F17: HU-1.1 — Levantar pedido | G17: Intentar adjuntar un archivo de más de 10 MB | H17: TC-A-1.1-15 | I17: EP-01 | J17: F-01 | K17: HU-1.1 | L17: Intentar adjuntar un archivo de más de 10 MB | M17: El sistema rechaza el archivo por superar el tamaño máximo y no lo incorpora a la solicitud. | N17: HIGH | O17: NEGATIVE | P17: Usuario Vendedor autenticado; formulario de solicitud disponible. | Q17: Archivo de más de 10 MB | R17: El sistema rechaza el archivo por superar el tamaño máximo y no lo incorpora a la solicitud. | S17: 1. Completar la solicitud. 2. Intentar adjuntar el archivo. | T17: El sistema rechaza el archivo por superar el tamaño máximo y no lo incorpora a la solicitud. | U17: PASS | V17: PASS | W17: TC-A-1.1-15 | X17: Modificado: El criterio pasa a ser archivo de más de 10 MB. (ref. D-6) | AA17: OFICIAL / BASELINE | AB17: PRD V2 + Backlog V2 + DB V2 + QA | AC17: Caso del alcance
A18: Épica 1 — Vendedor | B18: Circuito comercial del Vendedor: registro de solicitudes y gestión de cotizaciones derivadas. | C18: FUNCIONAL | D18: Levantar pedido | E18: Levantar pedido | F18: HU-1.1 — Levantar pedido | G18: Registrar solicitud sin archivo de documentación | H18: TC-A-1.1-16 | I18: EP-01 | J18: F-01 | K18: HU-1.1 | L18: Registrar solicitud sin archivo de documentación | M18: La solicitud se registra sin archivo cuando la documentación no es obligatoria en el diseño actual. | N18: MEDIUM | O18: FUNCTIONAL | P18: Usuario Vendedor autenticado; formulario de solicitud disponible. | Q18: Solicitud válida; sin archivo adjunto | R18: La solicitud se registra sin archivo cuando la documentación no es obligatoria en el diseño actual. | S18: 1. Completar la solicitud. 2. No adjuntar ningún archivo. 3. Guardar. | T18: La solicitud se registra sin archivo cuando la documentación no es obligatoria en el diseño actual. | U18: PASS | V18: PASS | W18: TC-A-1.1-16 | AA18: OFICIAL / BASELINE | AB18: PRD V2 + Backlog V2 + DB V2 + QA | AC18: Caso del alcance
A19: Épica 1 — Vendedor | B19: Circuito comercial del Vendedor: registro de solicitudes y gestión de cotizaciones derivadas. | C19: FUNCIONAL | D19: Levantar pedido | E19: Levantar pedido | F19: HU-1.1 — Levantar pedido | G19: Registrar cliente nuevo con un CUIT que ya existe | H19: TC-A-1.1-17 | I19: EP-01 | J19: F-01 | K19: HU-1.1 | L19: Registrar cliente nuevo con un CUIT que ya existe | M19: El sistema no registra el cliente e informa que el CUIT ya está registrado. | N19: HIGH | O19: NEGATIVE | P19: Usuario Vendedor autenticado; formulario de solicitud disponible. | Q19: CUIT de un cliente ya registrado; resto de los datos válidos | R19: El sistema no registra el cliente e informa que el CUIT ya está registrado. | S19: 1. Cargar un cliente nuevo con ese CUIT. 2. Completar la solicitud. 3. Intentar guardar. | T19: El sistema no registra el cliente e informa que el CUIT ya está registrado. | U19: PASS | V19: PASS | W19: TC-A-1.1-17 | X19: Nuevo: Cliente nuevo con un CUIT que ya existe. (ref. D-4) | AA19: OFICIAL / BASELINE | AB19: PRD V2 + Backlog V2 + DB V2 + QA | AC19: Caso del alcance
A20: Épica 1 — Vendedor | B20: Circuito comercial del Vendedor: registro de solicitudes y gestión de cotizaciones derivadas. | C20: FUNCIONAL | D20: Levantar pedido | E20: Levantar pedido | F20: HU-1.1 — Levantar pedido | G20: Registrar cliente nuevo sin email | H20: TC-A-1.1-18 | I20: EP-01 | J20: F-01 | K20: HU-1.1 | L20: Registrar cliente nuevo sin email | M20: La solicitud no se registra y el sistema señala que falta el email, que es obligatorio. | N20: HIGH | O20: NEGATIVE | P20: Usuario Vendedor autenticado; formulario de solicitud disponible. | Q20: Razón social, CUIT, contacto, dirección y teléfono válidos; email vacío | R20: La solicitud no se registra y el sistema señala que falta el email, que es obligatorio. | S20: 1. Completar los campos restantes. 2. Dejar email vacío. 3. Intentar guardar. | T20: La solicitud no se registra y el sistema señala que falta el email, que es obligatorio. | U20: PASS | V20: PASS | W20: TC-A-1.1-18 | X20: Nuevo: Cliente nuevo sin email. (ref. D-4) | AA20: OFICIAL / BASELINE | AB20: PRD V2 + Backlog V2 + DB V2 + QA | AC20: Caso del alcance
A21: Épica 1 — Vendedor | B21: Circuito comercial del Vendedor: registro de solicitudes y gestión de cotizaciones derivadas. | C21: FUNCIONAL | D21: Cotizaciones derivadas | E21: Cotizaciones derivadas | F21: HU-1.3 — Cotizaciones derivadas | G21: Vendedor consulta una cotización derivada de una solicitud | H21: TC-A-1.3-01 | I21: EP-01 | J21: F-03 | K21: HU-1.3 | L21: Vendedor consulta una cotización derivada de una solicitud | M21: El Vendedor puede consultar la cotización derivada de la solicitud. | N21: CRITICAL | O21: FUNCTIONAL | P21: Usuario Vendedor autenticado; cotización disponible. | Q21: Solicitud con cotización disponible | R21: El Vendedor puede consultar la cotización derivada de la solicitud. | S21: 1. Ingresar como Vendedor. 2. Consultar cotizaciones disponibles. 3. Seleccionar una cotización. | T21: El Vendedor puede consultar la cotización derivada de la solicitud. | U21: PASS | V21: PASS | W21: TC-A-1.3-01 | AA21: OFICIAL / BASELINE | AB21: PRD V2 + Backlog V2 + DB V2 + QA | AC21: Caso del alcance
A22: Épica 1 — Vendedor | B22: Circuito comercial del Vendedor: registro de solicitudes y gestión de cotizaciones derivadas. | C22: FUNCIONAL | D22: Cotizaciones derivadas | E22: Cotizaciones derivadas | F22: HU-1.3 — Cotizaciones derivadas | G22: Vendedor visualiza correctamente los datos de la cotización | H22: TC-A-1.3-02 | I22: EP-01 | J22: F-03 | K22: HU-1.3 | L22: Vendedor visualiza correctamente los datos de la cotización | M22: La información de la cotización se muestra de forma consistente con los datos registrados. | N22: HIGH | O22: FUNCTIONAL | P22: Usuario Vendedor autenticado; cotización disponible. | Q22: Cotización con datos completos | R22: La información de la cotización se muestra de forma consistente con los datos registrados. | S22: 1. Abrir la cotización. 2. Revisar cliente, solicitud, fases, tiempos y precio final. | T22: La información de la cotización se muestra de forma consistente con los datos registrados. | U22: PASS | V22: PASS | W22: TC-A-1.3-02 | AA22: OFICIAL / BASELINE | AB22: PRD V2 + Backlog V2 + DB V2 + QA | AC22: Caso del alcance
A23: Épica 1 — Vendedor | B23: Circuito comercial del Vendedor: registro de solicitudes y gestión de cotizaciones derivadas. | C23: FUNCIONAL | D23: Cotizaciones derivadas | E23: Cotizaciones derivadas | F23: HU-1.3 — Cotizaciones derivadas | G23: Vendedor registra aprobación de una cotización válida | H23: TC-A-1.3-03 | I23: EP-01 | J23: F-03 | K23: HU-1.3 | L23: Vendedor registra aprobación de una cotización válida | M23: La aprobación queda registrada correctamente. | N23: CRITICAL | O23: FUNCTIONAL | P23: Usuario Vendedor autenticado; cotización disponible. | Q23: Cotización válida disponible para decisión | R23: La aprobación queda registrada correctamente. | S23: 1. Abrir la cotización. 2. Seleccionar aprobación. 3. Confirmar la acción. | T23: La aprobación queda registrada correctamente. | U23: PASS | V23: PASS | W23: TC-A-1.3-03 | AA23: OFICIAL / BASELINE | AB23: PRD V2 + Backlog V2 + DB V2 + QA | AC23: Caso del alcance
A24: Épica 1 — Vendedor | B24: Circuito comercial del Vendedor: registro de solicitudes y gestión de cotizaciones derivadas. | C24: FUNCIONAL | D24: Cotizaciones derivadas | E24: Cotizaciones derivadas | F24: HU-1.3 — Cotizaciones derivadas | G24: Verificar cambio a estado APROBADA | H24: TC-A-1.3-04 | I24: EP-01 | J24: F-03 | K24: HU-1.3 | L24: Verificar cambio a estado APROBADA | M24: La cotización queda en estado APROBADA. | N24: CRITICAL | O24: INTEGRATION | P24: Usuario Vendedor autenticado; cotización disponible. | Q24: Cotización aprobada | R24: La cotización queda en estado APROBADA. | S24: 1. Registrar aprobación. 2. Consultar el estado de la cotización. | T24: La cotización queda en estado APROBADA. | U24: PASS | V24: PASS | W24: TC-A-1.3-04 | AA24: OFICIAL / BASELINE | AB24: PRD V2 + Backlog V2 + DB V2 + QA | AC24: Caso del alcance
A25: Épica 1 — Vendedor | B25: Circuito comercial del Vendedor: registro de solicitudes y gestión de cotizaciones derivadas. | C25: FUNCIONAL | D25: Cotizaciones derivadas | E25: Cotizaciones derivadas | F25: HU-1.3 — Cotizaciones derivadas | G25: Verificar generación automática de OT después de la aprobación | H25: TC-A-1.3-05 | I25: EP-01 | J25: F-03 | K25: HU-1.3 | L25: Verificar generación automática de OT después de la aprobación | M25: Se genera automáticamente una OT asociada a la cotización aprobada. | N25: CRITICAL | O25: E2E | P25: Usuario Vendedor autenticado; cotización disponible. | Q25: Cotización en estado APROBADA | R25: Se genera automáticamente una OT asociada a la cotización aprobada. | S25: 1. Aprobar la cotización. 2. Consultar las órdenes de trabajo generadas. | T25: Se genera automáticamente una OT asociada a la cotización aprobada. | U25: PASS | V25: PASS | W25: TC-A-1.3-05 | AA25: OFICIAL / BASELINE | AB25: PRD V2 + Backlog V2 + DB V2 + QA | AC25: Caso del alcance
A26: Épica 1 — Vendedor | B26: Circuito comercial del Vendedor: registro de solicitudes y gestión de cotizaciones derivadas. | C26: FUNCIONAL | D26: Cotizaciones derivadas | E26: Cotizaciones derivadas | F26: HU-1.3 — Cotizaciones derivadas | G26: Verificar que la OT quede asociada a la cotización aprobada | H26: TC-A-1.3-06 | I26: EP-01 | J26: F-03 | K26: HU-1.3 | L26: Verificar que la OT quede asociada a la cotización aprobada | M26: La OT queda correctamente asociada a la cotización aprobada. | N26: CRITICAL | O26: INTEGRATION | P26: Usuario Vendedor autenticado; cotización disponible. | Q26: Cotización aprobada; OT generada | R26: La OT queda correctamente asociada a la cotización aprobada. | S26: 1. Aprobar la cotización. 2. Consultar la OT. 3. Verificar su relación con la cotización. | T26: La OT queda correctamente asociada a la cotización aprobada. | U26: PASS | V26: PASS | W26: TC-A-1.3-06 | AA26: OFICIAL / BASELINE | AB26: PRD V2 + Backlog V2 + DB V2 + QA | AC26: Caso del alcance
A27: Épica 1 — Vendedor | B27: Circuito comercial del Vendedor: registro de solicitudes y gestión de cotizaciones derivadas. | C27: FUNCIONAL | D27: Cotizaciones derivadas | E27: Cotizaciones derivadas | F27: HU-1.3 — Cotizaciones derivadas | G27: Verificar que la primera fase de la OT quede en En Produccion | H27: TC-A-1.3-07 | I27: EP-01 | J27: F-03 | K27: HU-1.3 | L27: Verificar que la primera fase de la OT quede en EN_COLA | M27: La primera fase queda en estado EN_COLA. | N27: CRITICAL | O27: E2E | P27: Usuario Vendedor autenticado; cotización disponible. | Q27: OT generada con fases configuradas | R27: La primera fase queda en estado EN_COLA. | S27: 1. Aprobar la cotización. 2. Consultar las fases de la OT. | T27: La primera fase queda en estado EN_COLA. | U27: PASS | V27: PASS | W27: TC-A-1.3-07 | AA27: OFICIAL / BASELINE | AB27: PRD V2 + Backlog V2 + DB V2 + QA | AC27: Caso del alcance
A28: Épica 1 — Vendedor | B28: Circuito comercial del Vendedor: registro de solicitudes y gestión de cotizaciones derivadas. | C28: FUNCIONAL | D28: Cotizaciones derivadas | E28: Cotizaciones derivadas | F28: HU-1.3 — Cotizaciones derivadas | G28: Verificar que la primera fase quede asociada al operario correcto | H28: TC-A-1.3-08 | I28: EP-01 | J28: F-03 | K28: HU-1.3 | L28: Verificar que la primera fase quede asociada al operario correcto | M28: La primera fase queda visible/asociada al operario habilitado correspondiente. | N28: CRITICAL | O28: E2E | P28: Usuario Vendedor autenticado; cotización disponible. | Q28: OT generada; fase con operario habilitado | R28: La primera fase queda visible/asociada al operario habilitado correspondiente. | S28: 1. Aprobar la cotización. 2. Consultar la primera fase. 3. Verificar el operario asociado. | T28: La primera fase queda visible/asociada al operario habilitado correspondiente. | U28: PASS | V28: PASS | W28: TC-A-1.3-08 | AA28: OFICIAL / BASELINE | AB28: PRD V2 + Backlog V2 + DB V2 + QA | AC28: Caso del alcance
A29: Épica 1 — Vendedor | B29: Circuito comercial del Vendedor: registro de solicitudes y gestión de cotizaciones derivadas. | C29: FUNCIONAL | D29: Cotizaciones derivadas | E29: Cotizaciones derivadas | F29: HU-1.3 — Cotizaciones derivadas | G29: Vendedor registra cotización no aprobada | H29: TC-A-1.3-09 | I29: EP-01 | J29: F-03 | K29: HU-1.3 | L29: Vendedor registra cotización no aprobada | M29: La decisión de no aprobación queda registrada. | N29: HIGH | O29: FUNCTIONAL | P29: Usuario Vendedor autenticado; cotización disponible. | Q29: Cotización disponible para decisión | R29: La decisión de no aprobación queda registrada. | S29: 1. Abrir la cotización. 2. Seleccionar no aprobación. 3. Confirmar la acción. | T29: La decisión de no aprobación queda registrada. | U29: PASS | V29: PASS | W29: TC-A-1.3-09 | AA29: OFICIAL / BASELINE | AB29: PRD V2 + Backlog V2 + DB V2 + QA | AC29: Caso del alcance
A30: Épica 1 — Vendedor | B30: Circuito comercial del Vendedor: registro de solicitudes y gestión de cotizaciones derivadas. | C30: FUNCIONAL | D30: Cotizaciones derivadas | E30: Cotizaciones derivadas | F30: HU-1.3 — Cotizaciones derivadas | G30: Verificar estado NO_APROBADA | H30: TC-A-1.3-10 | I30: EP-01 | J30: F-03 | K30: HU-1.3 | L30: Verificar estado NO_APROBADA | M30: La cotización queda en estado NO_APROBADA. | N30: HIGH | O30: INTEGRATION | P30: Usuario Vendedor autenticado; cotización disponible. | Q30: Cotización no aprobada | R30: La cotización queda en estado NO_APROBADA. | S30: 1. Registrar la no aprobación. 2. Consultar el estado. | T30: La cotización queda en estado NO_APROBADA. | U30: PASS | V30: PASS | W30: TC-A-1.3-10 | AA30: OFICIAL / BASELINE | AB30: PRD V2 + Backlog V2 + DB V2 + QA | AC30: Caso del alcance
A31: Épica 1 — Vendedor | B31: Circuito comercial del Vendedor: registro de solicitudes y gestión de cotizaciones derivadas. | C31: FUNCIONAL | D31: Cotizaciones derivadas | E31: Cotizaciones derivadas | F31: HU-1.3 — Cotizaciones derivadas | G31: Verificar que una cotización no aprobada no genere OT | H31: TC-A-1.3-11 | I31: EP-01 | J31: F-03 | K31: HU-1.3 | L31: Verificar que una cotización no aprobada no genere OT | M31: No debe generarse una OT a partir de una cotización no aprobada. | N31: CRITICAL | O31: NEGATIVE | P31: Usuario Vendedor autenticado; cotización disponible. | Q31: Cotización en estado NO_APROBADA | R31: No debe generarse una OT a partir de una cotización no aprobada. | S31: 1. Registrar la no aprobación. 2. Consultar las OT asociadas. | T31: No debe generarse una OT a partir de una cotización no aprobada. | U31: PASS | V31: PASS | W31: TC-A-1.3-11 | AA31: OFICIAL / BASELINE | AB31: PRD V2 + Backlog V2 + DB V2 + QA | AC31: Caso del alcance
A32: Épica 1 — Vendedor | B32: Circuito comercial del Vendedor: registro de solicitudes y gestión de cotizaciones derivadas. | C32: FUNCIONAL | D32: Cotizaciones derivadas | E32: Cotizaciones derivadas | F32: HU-1.3 — Cotizaciones derivadas | G32: Intentar procesar nuevamente una cotización ya aprobada | H32: TC-A-1.3-12 | I32: EP-01 | J32: F-03 | K32: HU-1.3 | L32: Intentar procesar nuevamente una cotización ya aprobada | M32: El sistema no debe permitir una segunda transición no válida ni generar una OT duplicada. | N32: HIGH | O32: NEGATIVE | P32: Usuario Vendedor autenticado; cotización disponible. | Q32: Cotización en estado APROBADA; OT ya generada | R32: El sistema no debe permitir una segunda transición no válida ni generar una OT duplicada. | S32: 1. Consultar una cotización ya aprobada. 2. Intentar procesarla nuevamente. | T32: El sistema no debe permitir una segunda transición no válida ni generar una OT duplicada. | U32: PASS | V32: PASS | W32: TC-A-1.3-12 | AA32: OFICIAL / BASELINE | AB32: PRD V2 + Backlog V2 + DB V2 + QA | AC32: Caso del alcance
... A35: Épica 2 — Jefe de Producción | B35: Gestión de cotizaciones, órdenes de trabajo y planta. | C35: FUNCIONAL | D35: Recepción de cotización | E35: Recepción de cotización | F35: HU-2.1 — Recepción de cotización | G35: Jefe consulta una solicitud disponible para cotizar | H35: TC-A-2.1-01 | I35: EP-02 | J35: F-02 | K35: HU-2.1 | L35: Jefe consulta una solicitud disponible para cotizar | M35: La solicitud disponible para cotizar puede ser consultada por el Jefe. | N35: CRITICAL | O35: FUNCTIONAL | P35: Usuario Jefe de Producción autenticado; solicitud válida disponible. | Q35: Solicitud en estado PENDIENTE_COTIZACION | R35: La solicitud disponible para cotizar puede ser consultada por el Jefe. | S35: 1. Ingresar como Jefe. 2. Consultar solicitudes disponibles. 3. Seleccionar la solicitud. | T35: La solicitud disponible para cotizar puede ser consultada por el Jefe. | U35: PASS | V35: PASS | W35: TC-A-2.1-01 | AA35: OFICIAL / BASELINE | AB35: PRD V2 + Backlog V2 + DB V2 + QA | AC35: Caso del alcance
A36: Épica 2 — Jefe de Producción | B36: Gestión de cotizaciones, órdenes de trabajo y planta. | C36: FUNCIONAL | D36: Recepción de cotización | E36: Recepción de cotización | F36: HU-2.1 — Recepción de cotización | G36: Jefe selecciona fases del catálogo | H36: TC-A-2.1-02 | I36: EP-02 | J36: F-02 | K36: HU-2.1 | L36: Jefe selecciona fases del catálogo | M36: Solo se ofrecen fases con operarios habilitados, y las seleccionadas quedan incorporadas a la cotización. | N36: CRITICAL | O36: FUNCTIONAL | P36: Usuario Jefe de Producción autenticado; solicitud válida disponible. | Q36: Solicitud disponible; catálogo con fases que tienen operarios habilitados | R36: Solo se ofrecen fases con operarios habilitados, y las seleccionadas quedan incorporadas a la cotización. | S36: 1. Abrir la solicitud. 2. Consultar catálogo. 3. Seleccionar las fases necesarias. | T36: Solo se ofrecen fases con operarios habilitados, y las seleccionadas quedan incorporadas a la cotización. | U36: PASS | V36: PASS | W36: TC-A-2.1-02 | X36: Modificado: Solo se ofrecen fases con operarios habilitados. (ref. D-5) | AA36: OFICIAL / BASELINE | AB36: PRD V2 + Backlog V2 + DB V2 + QA | AC36: Caso del alcance
A37: Épica 2 — Jefe de Producción | B37: Gestión de cotizaciones, órdenes de trabajo y planta. | C37: FUNCIONAL | D37: Recepción de cotización | E37: Recepción de cotización | F37: HU-2.1 — Recepción de cotización | G37: Jefe define el orden de las fases | H37: TC-A-2.1-03 | I37: EP-02 | J37: F-02 | K37: HU-2.1 | L37: Jefe define el orden de las fases | M37: Las fases quedan registradas en el orden definido por el Jefe. | N37: HIGH | O37: FUNCTIONAL | P37: Usuario Jefe de Producción autenticado; solicitud válida disponible. | Q37: Solicitud con varias fases seleccionadas | R37: Las fases quedan registradas en el orden definido por el Jefe. | S37: 1. Seleccionar varias fases. 2. Definir el orden de ejecución. 3. Guardar la cotización. | T37: Las fases quedan registradas en el orden definido por el Jefe. | U37: PASS | V37: PASS | W37: TC-A-2.1-03 | AA37: OFICIAL / BASELINE | AB37: PRD V2 + Backlog V2 + DB V2 + QA | AC37: Caso del alcance
A38: Épica 2 — Jefe de Producción | B38: Gestión de cotizaciones, órdenes de trabajo y planta. | C38: FUNCIONAL | D38: Recepción de cotización | E38: Recepción de cotización | F38: HU-2.1 — Recepción de cotización | G38: Jefe utiliza una fase repetida cuando corresponde | H38: TC-A-2.1-04 | I38: EP-02 | J38: F-02 | K38: HU-2.1 | L38: Jefe utiliza una fase repetida cuando corresponde | M38: La cotización permite que una misma fase aparezca más de una vez cuando corresponde. | N38: HIGH | O38: VALIDATION | P38: Usuario Jefe de Producción autenticado; solicitud válida disponible. | Q38: Catálogo con una fase disponible para repetición | R38: La cotización permite que una misma fase aparezca más de una vez cuando corresponde. | S38: 1. Seleccionar una fase. 2. Incorporar nuevamente la misma fase cuando corresponda. 3. Definir el orden. | T38: La cotización permite que una misma fase aparezca más de una vez cuando corresponde. | U38: PASS | V38: PASS | W38: TC-A-2.1-04 | AA38: OFICIAL / BASELINE | AB38: PRD V2 + Backlog V2 + DB V2 + QA | AC38: Caso del alcance
A39: Épica 2 — Jefe de Producción | B39: Gestión de cotizaciones, órdenes de trabajo y planta. | C39: FUNCIONAL | D39: Recepción de cotización | E39: Recepción de cotización | F39: HU-2.1 — Recepción de cotización | G39: Jefe informa el tiempo estimado de las fases | H39: TC-A-2.1-05 | I39: EP-02 | J39: F-02 | K39: HU-2.1 | L39: Jefe informa el tiempo estimado de las fases | M39: Cada fase queda asociada al tiempo estimado informado. | N39: HIGH | O39: FUNCTIONAL | P39: Usuario Jefe de Producción autenticado; solicitud válida disponible. | Q39: Fases seleccionadas; tiempos estimados definidos | R39: Cada fase queda asociada al tiempo estimado informado. | S39: 1. Seleccionar las fases. 2. Informar el tiempo estimado de cada fase. 3. Guardar. | T39: Cada fase queda asociada al tiempo estimado informado. | U39: PASS | V39: PASS | W39: TC-A-2.1-05 | AA39: OFICIAL / BASELINE | AB39: PRD V2 + Backlog V2 + DB V2 + QA | AC39: Caso del alcance
A40: Épica 2 — Jefe de Producción | B40: Gestión de cotizaciones, órdenes de trabajo y planta. | C40: FUNCIONAL | D40: Recepción de cotización | E40: Recepción de cotización | F40: HU-2.1 — Recepción de cotización | G40: Verificar que la cotización mantenga un único precio final | H40: TC-A-2.1-06 | I40: EP-02 | J40: F-02 | K40: HU-2.1 | L40: Verificar que la cotización mantenga un único precio final | M40: La cotización mantiene un único precio final y no un precio individual por fase. | N40: HIGH | O40: VALIDATION | P40: Usuario Jefe de Producción autenticado; solicitud válida disponible. | Q40: Cotización con una o varias fases | R40: La cotización mantiene un único precio final y no un precio individual por fase. | S40: 1. Configurar las fases. 2. Informar el precio final. 3. Guardar la cotización. | T40: La cotización mantiene un único precio final y no un precio individual por fase. | U40: PASS | V40: PASS | W40: TC-A-2.1-06 | AA40: OFICIAL / BASELINE | AB40: PRD V2 + Backlog V2 + DB V2 + QA | AC40: Caso del alcance
A41: Épica 2 — Jefe de Producción | B41: Gestión de cotizaciones, órdenes de trabajo y planta. | C41: FUNCIONAL | D41: Recepción de cotización | E41: Recepción de cotización | F41: HU-2.1 — Recepción de cotización | G41: Generar y enviar la cotización asociada a la solicitud | H41: TC-A-2.1-07 | I41: EP-02 | J41: F-02 | K41: HU-2.1 | L41: Generar y enviar la cotización asociada a la solicitud | M41: La cotización queda asociada a la solicitud y disponible para el Vendedor. | N41: CRITICAL | O41: INTEGRATION | P41: Usuario Jefe de Producción autenticado; solicitud válida disponible. | Q41: Solicitud válida; cotización configurada | R41: La cotización queda asociada a la solicitud y disponible para el Vendedor. | S41: 1. Completar la cotización. 2. Guardar/generar la cotización. 3. Enviar la cotización al circuito correspondiente. | T41: La cotización queda asociada a la solicitud y disponible para el Vendedor. | U41: PASS | V41: PASS | W41: TC-A-2.1-07 | AA41: OFICIAL / BASELINE | AB41: PRD V2 + Backlog V2 + DB V2 + QA | AC41: Caso del alcance
A42: Épica 2 — Jefe de Producción | B42: Gestión de cotizaciones, órdenes de trabajo y planta. | C42: FUNCIONAL | D42: Recepción de cotización | E42: Recepción de cotización | F42: HU-2.1 — Recepción de cotización | G42: Verificar que la solicitud pasa a COTIZADA al crear su cotización | H42: TC-A-2.1-08 | I42: EP-02 | J42: F-02 | K42: HU-2.1 | L42: Verificar que la solicitud pasa a COTIZADA al crear su cotización | M42: La solicitud queda en COTIZADA. No figura en el listado del Jefe; sí figura, como "Cotizada", en el del Vendedor. La cotización queda en LISTA_PARA_ENVIAR. | N42: CRITICAL | O42: INTEGRATION | P42: Usuario Jefe de Producción autenticado; solicitud válida disponible. | Q42: Solicitud en estado PENDIENTE_COTIZACION, sin cotización | R42: La solicitud queda en COTIZADA. No figura en el listado del Jefe; sí figura, como "Cotizada", en el del Vendedor. La cotización queda en LISTA_PARA_ENVIAR. | S42: 1. Ingresar como Jefe. 2. Crear la cotización de esa solicitud. 3. Consultar GET /api/solicitudes como Jefe. 4. Consultar GET /api/solicitudes como Vendedor. 5. Consultar la cotización creada. | T42: La solicitud queda en COTIZADA. No figura en el listado del Jefe; sí figura, como "Cotizada", en el del Vendedor. La cotización queda en LISTA_PARA_ENVIAR. | U42: PASS | V42: PASS | W42: TC-A-2.1-08 | X42: Modificado: Se verifica la transición de la solicitud a `COTIZADA` y su visibilidad según rol. (ref. #156) | AA42: OFICIAL / BASELINE | AB42: PRD V2 + Backlog V2 + DB V2 + QA | AC42: Caso del alcance
...

Sheet LISTAS
A1: PRIORITY | B1: TYPE | C1: STATUS | D1: SEVERITY | E1: REQUERIMIENTO | G1: ALINEACIÓN
A2: CRITICAL | B2: FUNCTIONAL | C2: NOT RUN | D2: CRITICAL | E2: FUNCIONAL | G2: OFICIAL / BASELINE
A3: HIGH | B3: NEGATIVE | C3: PASS | D3: HIGH | E3: NO FUNCIONAL | G3: OFICIAL / INCORPORADO
A4: MEDIUM | B4: VALIDATION | C4: FAIL | D4: MEDIUM
A5: LOW | B5: INTEGRATION | C5: BLOCKED | D5: LOW
B6: E2E
B7: REGRESSION
B8: SECURITY
A11: Valores controlados. NOT RUN = diseñado/no ejecutado; PASS/FAIL/BLOCKED se completan durante la ejecución.

Sheet RESUMEN
A1: QualityTrack — Resumen de cobertura de casos de prueba
A3: Cobertura por área | B3: Casos | C3: NOT RUN | D3: PASS | E3: FAIL | F3: BLOCKED
A4: FASE A — HU-1.1 — Levantar pedido | B4: =COUNTIF('TEST-CASE'!$K$3:$K$159,"HU-1.1") -> 18 | C4: =COUNTIFS('TEST-CASE'!$K$3:$K$159,"HU-1.1",'TEST-CASE'!$V$3:$V$159,"NOT RUN") -> 0 | D4: =COUNTIFS('TEST-CASE'!$K$3:$K$159,"HU-1.1",'TEST-CASE'!$V$3:$V$159,"PASS") -> 17 | E4: =COUNTIFS('TEST-CASE'!$K$3:$K$159,"HU-1.1",'TEST-CASE'!$V$3:$V$159,"FAIL") -> 1 | F4: =COUNTIFS('TEST-CASE'!$K$3:$K$159,"HU-1.1",'TEST-CASE'!$V$3:$V$159,"BLOCKED") -> 0
A5: FASE A — HU-5.1 — Configuración de fases | B5: =COUNTIF('TEST-CASE'!$K$3:$K$159,"HU-5.1") -> 6 | C5: =COUNTIFS('TEST-CASE'!$K$3:$K$159,"HU-5.1",'TEST-CASE'!$V$3:$V$159,"NOT RUN") -> 0 | D5: =COUNTIFS('TEST-CASE'!$K$3:$K$159,"HU-5.1",'TEST-CASE'!$V$3:$V$159,"PASS") -> 5 | E5: =COUNTIFS('TEST-CASE'!$K$3:$K$159,"HU-5.1",'TEST-CASE'!$V$3:$V$159,"FAIL") -> 1 | F5: =COUNTIFS('TEST-CASE'!$K$3:$K$159,"HU-5.1",'TEST-CASE'!$V$3:$V$159,"BLOCKED") -> 0
A6: FASE A — HU-2.1 — Recepción de cotización | B6: =COUNTIF('TEST-CASE'!$K$3:$K$159,"HU-2.1") -> 8 | C6: =COUNTIFS('TEST-CASE'!$K$3:$K$159,"HU-2.1",'TEST-CASE'!$V$3:$V$159,"NOT RUN") -> 0 | D6: =COUNTIFS('TEST-CASE'!$K$3:$K$159,"HU-2.1",'TEST-CASE'!$V$3:$V$159,"PASS") -> 8 | E6: =COUNTIFS('TEST-CASE'!$K$3:$K$159,"HU-2.1",'TEST-CASE'!$V$3:$V$159,"FAIL") -> 0 | F6: =COUNTIFS('TEST-CASE'!$K$3:$K$159,"HU-2.1",'TEST-CASE'!$V$3:$V$159,"BLOCKED") -> 0
A7: FASE A — HU-1.3 — Cotizaciones derivadas | B7: =COUNTIF('TEST-CASE'!$K$3:$K$159,"HU-1.3") -> 14 | C7: =COUNTIFS('TEST-CASE'!$K$3:$K$159,"HU-1.3",'TEST-CASE'!$V$3:$V$159,"NOT RUN") -> 0 | D7: =COUNTIFS('TEST-CASE'!$K$3:$K$159,"HU-1.3",'TEST-CASE'!$V$3:$V$159,"PASS") -> 14 | E7: =COUNTIFS('TEST-CASE'!$K$3:$K$159,"HU-1.3",'TEST-CASE'!$V$3:$V$159,"FAIL") -> 0 | F7: =COUNTIFS('TEST-CASE'!$K$3:$K$159,"HU-1.3",'TEST-CASE'!$V$3:$V$159,"BLOCKED") -> 0
A8: FASE B — HU-3.1 — Tareas en ejecución y pendientes | B8: =COUNTIF('TEST-CASE'!$K$3:$K$159,"HU-3.1") -> 10 | C8: =COUNTIFS('TEST-CASE'!$K$3:$K$159,"HU-3.1",'TEST-CASE'!$V$3:$V$159,"NOT RUN") -> 0 | D8: =COUNTIFS('TEST-CASE'!$K$3:$K$159,"HU-3.1",'TEST-CASE'!$V$3:$V$159,"PASS") -> 10 | E8: =COUNTIFS('TEST-CASE'!$K$3:$K$159,"HU-3.1",'TEST-CASE'!$V$3:$V$159,"FAIL") -> 0 | F8: =COUNTIFS('TEST-CASE'!$K$3:$K$159,"HU-3.1",'TEST-CASE'!$V$3:$V$159,"BLOCKED") -> 0
A9: FASE B — HU-3.2 — Adjuntos | B9: =COUNTIF('TEST-CASE'!$K$3:$K$159,"HU-3.2") -> 5 | C9: =COUNTIFS('TEST-CASE'!$K$3:$K$159,"HU-3.2",'TEST-CASE'!$V$3:$V$159,"NOT RUN") -> 0 | D9: =COUNTIFS('TEST-CASE'!$K$3:$K$159,"HU-3.2",'TEST-CASE'!$V$3:$V$159,"PASS") -> 5 | E9: =COUNTIFS('TEST-CASE'!$K$3:$K$159,"HU-3.2",'TEST-CASE'!$V$3:$V$159,"FAIL") -> 0 | F9: =COUNTIFS('TEST-CASE'!$K$3:$K$159,"HU-3.2",'TEST-CASE'!$V$3:$V$159,"BLOCKED") -> 0
A10: FASE B — HU-3.3 — Vencimiento | B10: =COUNTIF('TEST-CASE'!$K$3:$K$159,"HU-3.3") -> 5 | C10: =COUNTIFS('TEST-CASE'!$K$3:$K$159,"HU-3.3",'TEST-CASE'!$V$3:$V$159,"NOT RUN") -> 0 | D10: =COUNTIFS('TEST-CASE'!$K$3:$K$159,"HU-3.3",'TEST-CASE'!$V$3:$V$159,"PASS") -> 5 | E10: =COUNTIFS('TEST-CASE'!$K$3:$K$159,"HU-3.3",'TEST-CASE'!$V$3:$V$159,"FAIL") -> 0 | F10: =COUNTIFS('TEST-CASE'!$K$3:$K$159,"HU-3.3",'TEST-CASE'!$V$3:$V$159,"BLOCKED") -> 0
A11: FASE B — HU-3.4 — Notas discriminadas por origen | B11: =COUNTIF('TEST-CASE'!$K$3:$K$159,"HU-3.4") -> 5 | C11: =COUNTIFS('TEST-CASE'!$K$3:$K$159,"HU-3.4",'TEST-CASE'!$V$3:$V$159,"NOT RUN") -> 0 | D11: =COUNTIFS('TEST-CASE'!$K$3:$K$159,"HU-3.4",'TEST-CASE'!$V$3:$V$159,"PASS") -> 5 | E11: =COUNTIFS('TEST-CASE'!$K$3:$K$159,"HU-3.4",'TEST-CASE'!$V$3:$V$159,"FAIL") -> 0 | F11: =COUNTIFS('TEST-CASE'!$K$3:$K$159,"HU-3.4",'TEST-CASE'!$V$3:$V$159,"BLOCKED") -> 0
A12: FASE B — HU-2.2 — Gestión de planta / reasignación | B12: =COUNTIF('TEST-CASE'!$K$3:$K$159,"HU-2.2") -> 6 | C12: =COUNTIFS('TEST-CASE'!$K$3:$K$159,"HU-2.2",'TEST-CASE'!$V$3:$V$159,"NOT RUN") -> 0 | D12: =COUNTIFS('TEST-CASE'!$K$3:$K$159,"HU-2.2",'TEST-CASE'!$V$3:$V$159,"PASS") -> 6 | E12: =COUNTIFS('TEST-CASE'!$K$3:$K$159,"HU-2.2",'TEST-CASE'!$V$3:$V$159,"FAIL") -> 0 | F12: =COUNTIFS('TEST-CASE'!$K$3:$K$159,"HU-2.2",'TEST-CASE'!$V$3:$V$159,"BLOCKED") -> 0
A13: FASE C — HU-4.1 — Órdenes terminadas | B13: =COUNTIF('TEST-CASE'!$K$3:$K$159,"HU-4.1") -> 5 | C13: =COUNTIFS('TEST-CASE'!$K$3:$K$159,"HU-4.1",'TEST-CASE'!$V$3:$V$159,"NOT RUN") -> 5 | D13: =COUNTIFS('TEST-CASE'!$K$3:$K$159,"HU-4.1",'TEST-CASE'!$V$3:$V$159,"PASS") -> 0 | E13: =COUNTIFS('TEST-CASE'!$K$3:$K$159,"HU-4.1",'TEST-CASE'!$V$3:$V$159,"FAIL") -> 0 | F13: =COUNTIFS('TEST-CASE'!$K$3:$K$159,"HU-4.1",'TEST-CASE'!$V$3:$V$159,"BLOCKED") -> 0
A14: FASE C — HU-4.2 — Auditoría / checklist | B14: =COUNTIF('TEST-CASE'!$K$3:$K$159,"HU-4.2") -> 9 | C14: =COUNTIFS('TEST-CASE'!$K$3:$K$159,"HU-4.2",'TEST-CASE'!$V$3:$V$159,"NOT RUN") -> 9 | D14: =COUNTIFS('TEST-CASE'!$K$3:$K$159,"HU-4.2",'TEST-CASE'!$V$3:$V$159,"PASS") -> 0 | E14: =COUNTIFS('TEST-CASE'!$K$3:$K$159,"HU-4.2",'TEST-CASE'!$V$3:$V$159,"FAIL") -> 0 | F14: =COUNTIFS('TEST-CASE'!$K$3:$K$159,"HU-4.2",'TEST-CASE'!$V$3:$V$159,"BLOCKED") -> 0
A15: FASE C — HU-4.3 — Veredicto | B15: =COUNTIF('TEST-CASE'!$K$3:$K$159,"HU-4.3") -> 5 | C15: =COUNTIFS('TEST-CASE'!$K$3:$K$159,"HU-4.3",'TEST-CASE'!$V$3:$V$159,"NOT RUN") -> 5 | D15: =COUNTIFS('TEST-CASE'!$K$3:$K$159,"HU-4.3",'TEST-CASE'!$V$3:$V$159,"PASS") -> 0 | E15: =COUNTIFS('TEST-CASE'!$K$3:$K$159,"HU-4.3",'TEST-CASE'!$V$3:$V$159,"FAIL") -> 0 | F15: =COUNTIFS('TEST-CASE'!$K$3:$K$159,"HU-4.3",'TEST-CASE'!$V$3:$V$159,"BLOCKED") -> 0
A16: FASE C — HU-2.3 — No conformidades / retrabajo | B16: =COUNTIF('TEST-CASE'!$K$3:$K$159,"HU-2.3") -> 8 | C16: =COUNTIFS('TEST-CASE'!$K$3:$K$159,"HU-2.3",'TEST-CASE'!$V$3:$V$159,"NOT RUN") -> 8 | D16: =COUNTIFS('TEST-CASE'!$K$3:$K$159,"HU-2.3",'TEST-CASE'!$V$3:$V$159,"PASS") -> 0 | E16: =COUNTIFS('TEST-CASE'!$K$3:$K$159,"HU-2.3",'TEST-CASE'!$V$3:$V$159,"FAIL") -> 0 | F16: =COUNTIFS('TEST-CASE'!$K$3:$K$159,"HU-2.3",'TEST-CASE'!$V$3:$V$159,"BLOCKED") -> 0
A17: FASE C — HU-1.4 — Despacho / Entrega | B17: =COUNTIF('TEST-CASE'!$K$3:$K$159,"HU-1.4") -> 7 | C17: =COUNTIFS('TEST-CASE'!$K$3:$K$159,"HU-1.4",'TEST-CASE'!$V$3:$V$159,"NOT RUN") -> 7 | D17: =COUNTIFS('TEST-CASE'!$K$3:$K$159,"HU-1.4",'TEST-CASE'!$V$3:$V$159,"PASS") -> 0 | E17: =COUNTIFS('TEST-CASE'!$K$3:$K$159,"HU-1.4",'TEST-CASE'!$V$3:$V$159,"FAIL") -> 0 | F17: =COUNTIFS('TEST-CASE'!$K$3:$K$159,"HU-1.4",'TEST-CASE'!$V$3:$V$159,"BLOCKED") -> 0
A18: FASE D — HU-1.2 — Buscar órdenes / expediente completo | B18: =COUNTIF('TEST-CASE'!$K$3:$K$159,"HU-1.2") -> 12 | C18: =COUNTIFS('TEST-CASE'!$K$3:$K$159,"HU-1.2",'TEST-CASE'!$V$3:$V$159,"NOT RUN") -> 12 | D18: =COUNTIFS('TEST-CASE'!$K$3:$K$159,"HU-1.2",'TEST-CASE'!$V$3:$V$159,"PASS") -> 0 | E18: =COUNTIFS('TEST-CASE'!$K$3:$K$159,"HU-1.2",'TEST-CASE'!$V$3:$V$159,"FAIL") -> 0 | F18: =COUNTIFS('TEST-CASE'!$K$3:$K$159,"HU-1.2",'TEST-CASE'!$V$3:$V$159,"BLOCKED") -> 0
A19: FASE D — HU-5.3 — Vista global de planta | B19: =COUNTIF('TEST-CASE'!$K$3:$K$159,"HU-5.3") -> 8 | C19: =COUNTIFS('TEST-CASE'!$K$3:$K$159,"HU-5.3",'TEST-CASE'!$V$3:$V$159,"NOT RUN") -> 8 | D19: =COUNTIFS('TEST-CASE'!$K$3:$K$159,"HU-5.3",'TEST-CASE'!$V$3:$V$159,"PASS") -> 0 | E19: =COUNTIFS('TEST-CASE'!$K$3:$K$159,"HU-5.3",'TEST-CASE'!$V$3:$V$159,"FAIL") -> 0 | F19: =COUNTIFS('TEST-CASE'!$K$3:$K$159,"HU-5.3",'TEST-CASE'!$V$3:$V$159,"BLOCKED") -> 0
A20: FASE D — HU-5.4 — Vista global de Calidad | B20: =COUNTIF('TEST-CASE'!$K$3:$K$159,"HU-5.4") -> 9 | C20: =COUNTIFS('TEST-CASE'!$K$3:$K$159,"HU-5.4",'TEST-CASE'!$V$3:$V$159,"NOT RUN") -> 9 | D20: =COUNTIFS('TEST-CASE'!$K$3:$K$159,"HU-5.4",'TEST-CASE'!$V$3:$V$159,"PASS") -> 0 | E20: =COUNTIFS('TEST-CASE'!$K$3:$K$159,"HU-5.4",'TEST-CASE'!$V$3:$V$159,"FAIL") -> 0 | F20: =COUNTIFS('TEST-CASE'!$K$3:$K$159,"HU-5.4",'TEST-CASE'!$V$3:$V$159,"BLOCKED") -> 0
A21: FASE A — E2E principal | B21: =COUNTIF('TEST-CASE'!$H$3:$H$156,"E2E-A-01") -> 1 | C21: =COUNTIFS('TEST-CASE'!$H$3:$H$156,"E2E-A-01",'TEST-CASE'!$V$3:$V$156,"NOT RUN") -> 0 | D21: =COUNTIFS('TEST-CASE'!$H$3:$H$156,"E2E-A-01",'TEST-CASE'!$V$3:$V$156,"PASS") -> 1 | E21: =COUNTIFS('TEST-CASE'!$H$3:$H$156,"E2E-A-01",'TEST-CASE'!$V$3:$V$156,"FAIL") -> 0 | F21: =COUNTIFS('TEST-CASE'!$H$3:$H$156,"E2E-A-01",'TEST-CASE'!$V$3:$V$156,"BLOCKED") -> 0
A22: FASE A — E2E negativos | B22: =COUNTIF('TEST-CASE'!$H$3:$H$156,"E2E-A-NEG-*") -> 4 | C22: =COUNTIFS('TEST-CASE'!$H$3:$H$156,"E2E-A-NEG-*",'TEST-CASE'!$V$3:$V$156,"NOT RUN") -> 0 | D22: =COUNTIFS('TEST-CASE'!$H$3:$H$156,"E2E-A-NEG-*",'TEST-CASE'!$V$3:$V$156,"PASS") -> 4 | E22: =COUNTIFS('TEST-CASE'!$H$3:$H$156,"E2E-A-NEG-*",'TEST-CASE'!$V$3:$V$156,"FAIL") -> 0 | F22: =COUNTIFS('TEST-CASE'!$H$3:$H$156,"E2E-A-NEG-*",'TEST-CASE'!$V$3:$V$156,"BLOCKED") -> 0
A23: FASE B — E2E principal | B23: =COUNTIF('TEST-CASE'!$H$3:$H$156,"E2E-B-01") -> 1 | C23: =COUNTIFS('TEST-CASE'!$H$3:$H$156,"E2E-B-01",'TEST-CASE'!$V$3:$V$156,"NOT RUN") -> 0 | D23: =COUNTIFS('TEST-CASE'!$H$3:$H$156,"E2E-B-01",'TEST-CASE'!$V$3:$V$156,"PASS") -> 1 | E23: =COUNTIFS('TEST-CASE'!$H$3:$H$156,"E2E-B-01",'TEST-CASE'!$V$3:$V$156,"FAIL") -> 0 | F23: =COUNTIFS('TEST-CASE'!$H$3:$H$156,"E2E-B-01",'TEST-CASE'!$V$3:$V$156,"BLOCKED") -> 0
A24: FASE B — E2E negativos | B24: =COUNTIF('TEST-CASE'!$H$3:$H$156,"E2E-B-NEG-*") -> 4 | C24: =COUNTIFS('TEST-CASE'!$H$3:$H$156,"E2E-B-NEG-*",'TEST-CASE'!$V$3:$V$156,"NOT RUN") -> 0 | D24: =COUNTIFS('TEST-CASE'!$H$3:$H$156,"E2E-B-NEG-*",'TEST-CASE'!$V$3:$V$156,"PASS") -> 4 | E24: =COUNTIFS('TEST-CASE'!$H$3:$H$156,"E2E-B-NEG-*",'TEST-CASE'!$V$3:$V$156,"FAIL") -> 0 | F24: =COUNTIFS('TEST-CASE'!$H$3:$H$156,"E2E-B-NEG-*",'TEST-CASE'!$V$3:$V$156,"BLOCKED") -> 0
A25: FASE C — E2E principal | B25: =COUNTIF('TEST-CASE'!$H$3:$H$156,"E2E-C-01") -> 1 | C25: =COUNTIFS('TEST-CASE'!$H$3:$H$156,"E2E-C-01",'TEST-CASE'!$V$3:$V$156,"NOT RUN") -> 1 | D25: =COUNTIFS('TEST-CASE'!$H$3:$H$156,"E2E-C-01",'TEST-CASE'!$V$3:$V$156,"PASS") -> 0 | E25: =COUNTIFS('TEST-CASE'!$H$3:$H$156,"E2E-C-01",'TEST-CASE'!$V$3:$V$156,"FAIL") -> 0 | F25: =COUNTIFS('TEST-CASE'!$H$3:$H$156,"E2E-C-01",'TEST-CASE'!$V$3:$V$156,"BLOCKED") -> 0
A26: FASE C — E2E negativos | B26: =COUNTIF('TEST-CASE'!$H$3:$H$156,"E2E-C-NEG-*") -> 5 | C26: =COUNTIFS('TEST-CASE'!$H$3:$H$156,"E2E-C-NEG-*",'TEST-CASE'!$V$3:$V$156,"NOT RUN") -> 5 | D26: =COUNTIFS('TEST-CASE'!$H$3:$H$156,"E2E-C-NEG-*",'TEST-CASE'!$V$3:$V$156,"PASS") -> 0 | E26: =COUNTIFS('TEST-CASE'!$H$3:$H$156,"E2E-C-NEG-*",'TEST-CASE'!$V$3:$V$156,"FAIL") -> 0 | F26: =COUNTIFS('TEST-CASE'!$H$3:$H$156,"E2E-C-NEG-*",'TEST-CASE'!$V$3:$V$156,"BLOCKED") -> 0
A27: FASE D — E2E principal | B27: =COUNTIF('TEST-CASE'!$H$3:$H$156,"E2E-D-01") -> 0 | C27: =COUNTIFS('TEST-CASE'!$H$3:$H$156,"E2E-D-01",'TEST-CASE'!$V$3:$V$156,"NOT RUN") -> 0 | D27: =COUNTIFS('TEST-CASE'!$H$3:$H$156,"E2E-D-01",'TEST-CASE'!$V$3:$V$156,"PASS") -> 0 | E27: =COUNTIFS('TEST-CASE'!$H$3:$H$156,"E2E-D-01",'TEST-CASE'!$V$3:$V$156,"FAIL") -> 0 | F27: =COUNTIFS('TEST-CASE'!$H$3:$H$156,"E2E-D-01",'TEST-CASE'!$V$3:$V$156,"BLOCKED") -> 0
A28: FASE D — E2E negativos | B28: =COUNTIF('TEST-CASE'!$H$3:$H$156,"E2E-D-NEG-*") -> 0 | C28: =COUNTIFS('TEST-CASE'!$H$3:$H$156,"E2E-D-NEG-*",'TEST-CASE'!$V$3:$V$156,"NOT RUN") -> 0 | D28: =COUNTIFS('TEST-CASE'!$H$3:$H$156,"E2E-D-NEG-*",'TEST-CASE'!$V$3:$V$156,"PASS") -> 0 | E28: =COUNTIFS('TEST-CASE'!$H$3:$H$156,"E2E-D-NEG-*",'TEST-CASE'!$V$3:$V$156,"FAIL") -> 0 | F28: =COUNTIFS('TEST-CASE'!$H$3:$H$156,"E2E-D-NEG-*",'TEST-CASE'!$V$3:$V$156,"BLOCKED") -> 0
A29: TOTAL FASE A | B29: =COUNTIF('TEST-CASE'!$H$3:$H$156,"*-A-*") -> 51 | C29: =COUNTIFS('TEST-CASE'!$H$3:$H$156,"*-A-*",'TEST-CASE'!$V$3:$V$156,"NOT RUN") -> 0 | D29: =COUNTIFS('TEST-CASE'!$H$3:$H$156,"*-A-*",'TEST-CASE'!$V$3:$V$156,"PASS") -> 49 | E29: =COUNTIFS('TEST-CASE'!$H$3:$H$156,"*-A-*",'TEST-CASE'!$V$3:$V$156,"FAIL") -> 2 | F29: =COUNTIFS('TEST-CASE'!$H$3:$H$156,"*-A-*",'TEST-CASE'!$V$3:$V$156,"BLOCKED") -> 0
A30: TOTAL FASE B | B30: =COUNTIF('TEST-CASE'!$H$3:$H$156,"*-B-*") -> 36 | C30: =COUNTIFS('TEST-CASE'!$H$3:$H$156,"*-B-*",'TEST-CASE'!$V$3:$V$156,"NOT RUN") -> 0 | D30: =COUNTIFS('TEST-CASE'!$H$3:$H$156,"*-B-*",'TEST-CASE'!$V$3:$V$156,"PASS") -> 36 | E30: =COUNTIFS('TEST-CASE'!$H$3:$H$156,"*-B-*",'TEST-CASE'!$V$3:$V$156,"FAIL") -> 0 | F30: =COUNTIFS('TEST-CASE'!$H$3:$H$156,"*-B-*",'TEST-CASE'!$V$3:$V$156,"BLOCKED") -> 0
A31: TOTAL FASE C | B31: =COUNTIF('TEST-CASE'!$H$3:$H$156,"*-C-*") -> 40 | C31: =COUNTIFS('TEST-CASE'!$H$3:$H$156,"*-C-*",'TEST-CASE'!$V$3:$V$156,"NOT RUN") -> 40 | D31: =COUNTIFS('TEST-CASE'!$H$3:$H$156,"*-C-*",'TEST-CASE'!$V$3:$V$156,"PASS") -> 0 | E31: =COUNTIFS('TEST-CASE'!$H$3:$H$156,"*-C-*",'TEST-CASE'!$V$3:$V$156,"FAIL") -> 0 | F31: =COUNTIFS('TEST-CASE'!$H$3:$H$156,"*-C-*",'TEST-CASE'!$V$3:$V$156,"BLOCKED") -> 0
A32: TOTAL FASE D | B32: =COUNTIF('TEST-CASE'!$H$3:$H$156,"*-D-*") -> 27 | C32: =COUNTIFS('TEST-CASE'!$H$3:$H$156,"*-D-*",'TEST-CASE'!$V$3:$V$156,"NOT RUN") -> 27 | D32: =COUNTIFS('TEST-CASE'!$H$3:$H$156,"*-D-*",'TEST-CASE'!$V$3:$V$156,"PASS") -> 0 | E32: =COUNTIFS('TEST-CASE'!$H$3:$H$156,"*-D-*",'TEST-CASE'!$V$3:$V$156,"FAIL") -> 0 | F32: =COUNTIFS('TEST-CASE'!$H$3:$H$156,"*-D-*",'TEST-CASE'!$V$3:$V$156,"BLOCKED") -> 0
A33: TOTAL GENERAL A-D | B33: =COUNTA('TEST-CASE'!$H$3:$H$156) -> 154 | C33: =COUNTIF('TEST-CASE'!$V$3:$V$156,"NOT RUN") -> 67 | D33: =COUNTIF('TEST-CASE'!$V$3:$V$156,"PASS") -> 85 | E33: =COUNTIF('TEST-CASE'!$V$3:$V$156,"FAIL") -> 2 | F33: =COUNTIF('TEST-CASE'!$V$3:$V$156,"BLOCKED") -> 0
A36: Casos por prioridad | B36: Casos
A37: CRITICAL | B37: =COUNTIF('TEST-CASE'!$N$3:$N$156,"CRITICAL") -> 36
A38: HIGH | B38: =COUNTIF('TEST-CASE'!$N$3:$N$156,"HIGH") -> 42
A39: MEDIUM | B39: =COUNTIF('TEST-CASE'!$N$3:$N$156,"MEDIUM") -> 76
A40: LOW | B40: =COUNTIF('TEST-CASE'!$N$3:$N$156,"LOW") -> 0
A42: Casos por tipo | B42: Casos
A43: FUNCTIONAL | B43: =COUNTIF('TEST-CASE'!$O$3:$O$156,"FUNCTIONAL") -> 107
A44: NEGATIVE | B44: =COUNTIF('TEST-CASE'!$O$3:$O$156,"NEGATIVE") -> 15
...

Sheet CONTROL_PROYECTO
A1: QualityTrack — Control de alineación de la matriz con el proyecto
A2: Resultado | B2: Baseline por fases = 157 casos ejecutables.
A3: La baseline se contrastó con PRD V2, Backlog V2, DB V2, Análisis QA, flujo unificado, auditoría 25/09, PM y PRs relevantes. Los casos retirados se preservan en NO_BASELINE.
A4: FUENTE / REFERENCIA | B4: USO | C4: RESULTADO
A5: PRD V2 | B5: Flujo, roles, estados, alcance y reglas. | C5: ALINEADO
A6: Backlog V2 | B6: 17 HUs activas; HU-5.2 eliminada; criterios de aceptación. | C6: ALINEADO
A7: DB V2 | B7: Integridad, estados, CUIT, adjuntos y trazabilidad. | C7: ALINEADO
A8: Análisis Funcional QA v2 | B8: Base para escenarios, E2E y reglas transversales. | C8: ALINEADO
A9: PR #202 | B9: Formaliza D-1 a D-6 en documentación. | C9: INCORPORADO
A10: PR #160 / #161 / #188 | B10: D-4: CUIT único y datos obligatorios. | C10: INCORPORADO
A11: PR #199 | B11: D-6: adjuntos en BD, 10 MB, visualización. | C11: INCORPORADO
A12: PR #201 | B12: D-5: fases con operadores habilitados. | C12: INCORPORADO
A13: PR #228 | B13: Actualización PM de la matriz Fase A y cambios del 25/09. | C13: CONSIDERADO / HISTÓRICO
A14: Issue #105 / PR #106 | B14: Antecedente de diseño de matriz Fase A. | C14: PRESERVADO
A17: CONTROL DE FASES
A18: Fase | B18: Casos baseline | C18: Casos derivados | D18: Total
A19: Fase A | B19: 51 | C19: 0 | D19: 51
A20: Fase B | B20: 36 | C20: 0 | D20: 36
A21: Fase C | B21: 40 | C21: 0 | D21: 40
A22: Fase D | B22: 30 | C22: 0 | D22: 30
A23: TOTAL | B23: 157 | C23: 0 | D23: 157
A25: CAMBIOS / DECISIONES | B25: DETALLE
A26: A-1 | B26: E2E-A-NEG-04 no está en el Excel actual y no se reutiliza. | C26: D-5 lo eliminó del alcance; no se incorpora.
A27: D-1 | B27: Se retiraron E2E-D-NEG-01 a 04 de la baseline. | C27: Son negativos QA adicionales válidos, pero no forman parte de los 30 casos base de Fase D; quedan preservados en NO_BASELINE.
A28: D-2 | B28: Se agregaron TC-D-1.2-09 a 12. | C28: Faltaban en el Excel y están en la matriz funcional vigente.
A29: D-3 | B29: Se agregó TC-D-5.3-08. | C29: Faltaba en el Excel y está en la matriz funcional vigente.
A30: D-4 | B30: Se agregó TC-D-5.4-09. | C30: Faltaba en el Excel y está en la matriz funcional vigente.
A31: Ejecución | B31: Todos los casos permanecen NOT RUN. | C31: Result, Evidence, Defect ID y Severity quedan para la ejecución real.

Sheet NO_BASELINE
A1: ID TC | B1: Fase | C1: Decisión | D1: Motivo | E1: Uso futuro
A2: E2E-D-NEG-01 | B2: D | C2: NO BASELINE | D2: Consulta de OT inexistente: negativo QA adicional, no incluido en los 30 casos base de Fase D. | E2: Candidato para regresión/negativos.
A3: E2E-D-NEG-02 | B3: D | C3: NO BASELINE | D3: Inconsistencia expediente vs vista global: negativo QA adicional. | E3: Candidato para regresión/integración.
A4: E2E-D-NEG-03 | B4: D | C4: NO BASELINE | D4: Indicadores sin datos suficientes: negativo QA adicional. | E4: Candidato para validación de datos.
A5: E2E-D-NEG-04 | B5: D | C5: NO BASELINE | D5: Mezcla de datos entre órdenes: negativo QA adicional. | E5: Candidato para integridad/segregación.
A6: E2E-A-NEG-04 | B6: A | C6: ELIMINADO | D6: D-5: una fase no puede crearse sin operadores habilitados. El escenario dejó de ser válido; el ID no se reutiliza. | E6: Solo referencia histórica.

Sheet TRAZABILIDAD
A1: ID TC | B1: Alineación | C1: Fuente principal | D1: PR / decisión | E1: Observación
A2: TC-A-1.1-01 | B2: OFICIAL | C2: HU-1.1 / D-4 | D2: PR #160 + #161 + #188 + #202 | E2: Datos obligatorios y CUIT único.
A3: TC-A-1.1-02 | B3: OFICIAL / BASELINE | C3: PRD V2 + Backlog V2 + DB V2 + QA | D3: Según HU/fase | E3: Caso base de ejecución.
A4: TC-A-1.1-03 | B4: OFICIAL | C4: HU-1.1 / D-4 | D4: PR #160 + #161 + #188 + #202 | E4: Datos obligatorios y CUIT único.
A5: TC-A-1.1-04 | B5: OFICIAL | C5: HU-1.1 / D-4 | D5: PR #160 + #161 + #188 + #202 | E5: Datos obligatorios y CUIT único.
A6: TC-A-1.1-05 | B6: OFICIAL / BASELINE | C6: PRD V2 + Backlog V2 + DB V2 + QA | D6: Según HU/fase | E6: Caso base de ejecución.
A7: TC-A-1.1-06 | B7: OFICIAL / BASELINE | C7: PRD V2 + Backlog V2 + DB V2 + QA | D7: Según HU/fase | E7: Caso base de ejecución.
A8: TC-A-1.1-07 | B8: OFICIAL / BASELINE | C8: PRD V2 + Backlog V2 + DB V2 + QA | D8: Según HU/fase | E8: Caso base de ejecución.
A9: TC-A-1.1-08 | B9: OFICIAL / BASELINE | C9: PRD V2 + Backlog V2 + DB V2 + QA | D9: Según HU/fase | E9: Caso base de ejecución.
A10: TC-A-1.1-09 | B10: OFICIAL / BASELINE | C10: PRD V2 + Backlog V2 + DB V2 + QA | D10: Según HU/fase | E10: Caso base de ejecución.
