Workbook

Sheet TEST-CASE
A1: QualityTrack — MVP · Matriz de Casos de Prueba · Fase A — Circuito comercial · S1 → S2 · Versión 1.1 · Responsable QA: María Chiribao · Estado: Correcta / lista para incorporación a GitHub
A2: EPICS | B2: EPIC DESCRIPTION | C2: REQUERIMIENTO | D2: FEATURES | E2: FEATURE DESCRIPTION | F2: USER STORY | G2: SCENARIO | H2: ID TC | I2: ID EP | J2: ID F | K2: ID US | L2: Title | M2: Description | N2: Priority | O2: Type | P2: Pre-requisites | Q2: Test Data | R2: Acceptance Criteria | S2: Steps | T2: Expected Result | U2: Result | V2: Status | W2: Evidence | X2: Comments | Y2: Defect ID | Z2: Severity
A3: Épica 1 — Vendedor | B3: Circuito comercial del Vendedor: registro de solicitudes y gestión de cotizaciones derivadas. | C3: FUNCIONAL | D3: Levantar pedido | E3: Registro de la solicitud que inicia el circuito comercial, incluyendo cliente y documentación. | F3: Como Vendedor quiero registrar una solicitud para iniciar el proceso comercial | G3: Dado que el Vendedor está autenticado Cuando completa los datos obligatorios y opcionales válidos y guarda Entonces la solicitud se registra correctamente | H3: TC-A-1.1-01 | I3: EP-01 | J3: F-01 | K3: US-1.1 | L3: Registrar solicitud con datos válidos | M3: Registrar una solicitud utilizando los datos obligatorios y datos opcionales válidos. | N3: HIGH | O3: FUNCTIONAL | P3: Usuario Vendedor autenticado. | Q3: Razón social, dirección y teléfono válidos; descripción de pieza/trabajo; cantidad > 0. | R3: La solicitud debe registrarse correctamente. | S3: 1. Ingresar los datos del cliente. 2. Ingresar la descripción de pieza/trabajo. 3. Informar la cantidad. 4. Guardar la solicitud. | T3: La solicitud se crea correctamente y queda disponible para continuar el circuito comercial. | U3: PASS | V3: PASS
A4: Épica 1 — Vendedor | B4: Circuito comercial del Vendedor: registro de solicitudes y gestión de cotizaciones derivadas. | C4: FUNCIONAL | D4: Levantar pedido | E4: Registro de la solicitud que inicia el circuito comercial, incluyendo cliente y documentación. | F4: Como Vendedor quiero registrar una solicitud para iniciar el proceso comercial | G4: Dado que el Vendedor no informa la razón social Cuando intenta guardar la solicitud Entonces el sistema no debe registrarla | H4: TC-A-1.1-02 | I4: EP-01 | J4: F-01 | K4: US-1.1 | L4: Registrar solicitud sin razón social | M4: Intentar registrar una solicitud sin informar la razón social. | N4: HIGH | O4: NEGATIVE | P4: Usuario Vendedor autenticado. | Q4: Razón social vacía; demás datos válidos. | R4: La razón social es obligatoria. | S4: 1. Completar los campos restantes. 2. Dejar la razón social vacía. 3. Intentar guardar. | T4: El sistema impide registrar la solicitud y solicita completar la razón social. | U4: PASS | V4: PASS
A5: Épica 1 — Vendedor | B5: Circuito comercial del Vendedor: registro de solicitudes y gestión de cotizaciones derivadas. | C5: FUNCIONAL | D5: Levantar pedido | E5: Registro de la solicitud que inicia el circuito comercial, incluyendo cliente y documentación. | F5: Como Vendedor quiero registrar una solicitud para iniciar el proceso comercial | G5: Dado que la dirección es un campo opcional Cuando el Vendedor guarda la solicitud sin informarla Entonces la solicitud se registra correctamente | H5: TC-A-1.1-03 | I5: EP-01 | J5: F-01 | K5: US-1.1 | L5: Registrar solicitud sin dirección | M5: Registrar una solicitud sin informar dirección. | N5: MEDIUM | O5: FUNCTIONAL | P5: Usuario Vendedor autenticado. | Q5: Razón social válida; dirección vacía; teléfono válido; demás datos válidos. | R5: La dirección es opcional en el diseño actual. | S5: 1. Completar los campos restantes. 2. Dejar la dirección vacía. 3. Guardar. | T5: La solicitud se registra correctamente sin dirección. | V5: FAIL | X5: Posible mejora futura — evaluar si debería pasar a ser obligatorio.
A6: Épica 1 — Vendedor | B6: Circuito comercial del Vendedor: registro de solicitudes y gestión de cotizaciones derivadas. | C6: FUNCIONAL | D6: Levantar pedido | E6: Registro de la solicitud que inicia el circuito comercial, incluyendo cliente y documentación. | F6: Como Vendedor quiero registrar una solicitud para iniciar el proceso comercial | G6: Dado que el teléfono es un campo opcional Cuando el Vendedor guarda la solicitud sin informarlo Entonces la solicitud se registra correctamente | H6: TC-A-1.1-04 | I6: EP-01 | J6: F-01 | K6: US-1.1 | L6: Registrar solicitud sin teléfono | M6: Registrar una solicitud sin informar teléfono. | N6: MEDIUM | O6: FUNCTIONAL | P6: Usuario Vendedor autenticado. | Q6: Razón social válida; teléfono vacío; dirección válida; demás datos válidos. | R6: El teléfono es opcional en el diseño actual. | S6: 1. Completar los campos restantes. 2. Dejar el teléfono vacío. 3. Guardar. | T6: La solicitud se registra correctamente sin teléfono. | V6: NOT RUN | X6: Posible mejora futura — evaluar si debería pasar a ser obligatorio.
A7: Épica 1 — Vendedor | B7: Circuito comercial del Vendedor: registro de solicitudes y gestión de cotizaciones derivadas. | C7: FUNCIONAL | D7: Levantar pedido | E7: Registro de la solicitud que inicia el circuito comercial, incluyendo cliente y documentación. | F7: Como Vendedor quiero registrar una solicitud para iniciar el proceso comercial | G7: Dado que el Vendedor no informa la descripción de pieza/trabajo Cuando intenta guardar la solicitud Entonces el sistema no debe registrarla | H7: TC-A-1.1-05 | I7: EP-01 | J7: F-01 | K7: US-1.1 | L7: Registrar solicitud sin descripción de pieza/trabajo | M7: Intentar registrar una solicitud sin descripción de la pieza o trabajo. | N7: HIGH | O7: NEGATIVE | P7: Usuario Vendedor autenticado. | Q7: Descripción vacía; demás datos válidos. | R7: La descripción es obligatoria. | S7: 1. Completar los datos del cliente. 2. Dejar la descripción vacía. 3. Informar la cantidad. 4. Intentar guardar. | T7: El sistema impide registrar la solicitud. | V7: NOT RUN
A8: Épica 1 — Vendedor | B8: Circuito comercial del Vendedor: registro de solicitudes y gestión de cotizaciones derivadas. | C8: FUNCIONAL | D8: Levantar pedido | E8: Registro de la solicitud que inicia el circuito comercial, incluyendo cliente y documentación. | F8: Como Vendedor quiero registrar una solicitud para iniciar el proceso comercial | G8: Dado que el Vendedor no informa la cantidad Cuando intenta guardar la solicitud Entonces el sistema no debe registrarla | H8: TC-A-1.1-06 | I8: EP-01 | J8: F-01 | K8: US-1.1 | L8: Registrar solicitud sin cantidad | M8: Intentar registrar una solicitud sin informar cantidad. | N8: HIGH | O8: NEGATIVE | P8: Usuario Vendedor autenticado. | Q8: Cantidad vacía; demás datos válidos. | R8: La cantidad es obligatoria. | S8: 1. Completar los datos obligatorios del cliente. 2. Informar la descripción. 3. Dejar la cantidad vacía. 4. Intentar guardar. | T8: El sistema impide registrar la solicitud. | V8: NOT RUN
A9: Épica 1 — Vendedor | B9: Circuito comercial del Vendedor: registro de solicitudes y gestión de cotizaciones derivadas. | C9: FUNCIONAL | D9: Levantar pedido | E9: Registro de la solicitud que inicia el circuito comercial, incluyendo cliente y documentación. | F9: Como Vendedor quiero registrar una solicitud para iniciar el proceso comercial | G9: Dado que el Vendedor informa una cantidad igual a 0 Cuando intenta guardar la solicitud Entonces el sistema rechaza el valor | H9: TC-A-1.1-07 | I9: EP-01 | J9: F-01 | K9: US-1.1 | L9: Registrar solicitud con cantidad 0 | M9: Intentar registrar una solicitud con cantidad igual a cero. | N9: HIGH | O9: VALIDATION | P9: Usuario Vendedor autenticado. | Q9: Cantidad = 0. | R9: La cantidad debe ser mayor que 0. | S9: 1. Completar los datos obligatorios. 2. Informar cantidad = 0. 3. Intentar guardar. | T9: El sistema rechaza el valor y no registra la solicitud. | V9: NOT RUN
A10: Épica 1 — Vendedor | B10: Circuito comercial del Vendedor: registro de solicitudes y gestión de cotizaciones derivadas. | C10: FUNCIONAL | D10: Levantar pedido | E10: Registro de la solicitud que inicia el circuito comercial, incluyendo cliente y documentación. | F10: Como Vendedor quiero registrar una solicitud para iniciar el proceso comercial | G10: Dado que el Vendedor informa una cantidad negativa Cuando intenta guardar la solicitud Entonces el sistema rechaza el valor | H10: TC-A-1.1-08 | I10: EP-01 | J10: F-01 | K10: US-1.1 | L10: Registrar solicitud con cantidad negativa | M10: Intentar registrar una solicitud con cantidad menor que cero. | N10: HIGH | O10: VALIDATION | P10: Usuario Vendedor autenticado. | Q10: Cantidad = -1. | R10: La cantidad debe ser mayor que 0. | S10: 1. Completar los datos obligatorios. 2. Informar cantidad = -1. 3. Intentar guardar. | T10: El sistema rechaza el valor y no registra la solicitud. | V10: NOT RUN
A11: Épica 1 — Vendedor | B11: Circuito comercial del Vendedor: registro de solicitudes y gestión de cotizaciones derivadas. | C11: FUNCIONAL | D11: Levantar pedido | E11: Registro de la solicitud que inicia el circuito comercial, incluyendo cliente y documentación. | F11: Como Vendedor quiero registrar una solicitud para iniciar el proceso comercial | G11: Dado que el Vendedor informa una cantidad mayor que 0 Cuando guarda la solicitud Entonces la solicitud se registra correctamente | H11: TC-A-1.1-09 | I11: EP-01 | J11: F-01 | K11: US-1.1 | L11: Registrar solicitud con cantidad mayor que 0 | M11: Registrar una solicitud con cantidad válida. | N11: MEDIUM | O11: FUNCTIONAL | P11: Usuario Vendedor autenticado. | Q11: Cantidad > 0. | R11: La cantidad válida permite registrar la solicitud. | S11: 1. Completar los datos obligatorios. 2. Informar una cantidad mayor que 0. 3. Guardar. | T11: La solicitud se registra correctamente. | V11: NOT RUN
A12: Épica 1 — Vendedor | B12: Circuito comercial del Vendedor: registro de solicitudes y gestión de cotizaciones derivadas. | C12: FUNCIONAL | D12: Levantar pedido | E12: Registro de la solicitud que inicia el circuito comercial, incluyendo cliente y documentación. | F12: Como Vendedor quiero registrar una solicitud para iniciar el proceso comercial | G12: Dado que la solicitud fue registrada Cuando se consulta su estado Entonces figura en PENDIENTE_COTIZACION | H12: TC-A-1.1-10 | I12: EP-01 | J12: F-01 | K12: US-1.1 | L12: Verificar estado inicial de la solicitud | M12: Comprobar el estado asignado al registrar la solicitud. | N12: HIGH | O12: VALIDATION | P12: Solicitud registrada correctamente. | Q12: Solicitud válida. | R12: El estado inicial debe ser PENDIENTE_COTIZACION. | S12: 1. Registrar la solicitud. 2. Consultar su estado. | T12: La solicitud queda en estado PENDIENTE_COTIZACION. | V12: NOT RUN
A13: Épica 1 — Vendedor | B13: Circuito comercial del Vendedor: registro de solicitudes y gestión de cotizaciones derivadas. | C13: FUNCIONAL | D13: Levantar pedido | E13: Registro de la solicitud que inicia el circuito comercial, incluyendo cliente y documentación. | F13: Como Vendedor quiero registrar una solicitud para iniciar el proceso comercial | G13: Dado que la solicitud fue registrada Cuando se la consulta posteriormente Entonces sus datos se conservan sin alteraciones | H13: TC-A-1.1-11 | I13: EP-01 | J13: F-01 | K13: US-1.1 | L13: Verificar persistencia de la solicitud | M13: Consultar nuevamente la solicitud luego de su registro. | N13: HIGH | O13: INTEGRATION | P13: Solicitud registrada. | Q13: Datos de solicitud válida. | R13: Los datos registrados deben conservarse. | S13: 1. Registrar la solicitud. 2. Consultar la solicitud posteriormente. 3. Comparar los datos registrados. | T13: La solicitud permanece disponible con sus datos correctamente almacenados. | V13: NOT RUN
A14: Épica 1 — Vendedor | B14: Circuito comercial del Vendedor: registro de solicitudes y gestión de cotizaciones derivadas. | C14: FUNCIONAL | D14: Levantar pedido | E14: Registro de la solicitud que inicia el circuito comercial, incluyendo cliente y documentación. | F14: Como Vendedor quiero registrar una solicitud para iniciar el proceso comercial | G14: Dado que el cliente ya existe en el sistema Cuando el Vendedor registra la solicitud con ese cliente Entonces la solicitud queda asociada al cliente existente | H14: TC-A-1.1-12 | I14: EP-01 | J14: F-01 | K14: US-1.1 | L14: Registrar solicitud con cliente existente | M14: Registrar una solicitud utilizando un cliente_id existente. | N14: HIGH | O14: FUNCTIONAL | P14: Usuario Vendedor autenticado; cliente existente. | Q14: cliente_id válido y existente. | R14: El cliente existente puede asociarse a la solicitud. | S14: 1. Seleccionar un cliente existente. 2. Completar descripción y cantidad. 3. Guardar la solicitud. | T14: La solicitud se registra asociada al cliente correspondiente. | V14: NOT RUN
A15: Épica 1 — Vendedor | B15: Circuito comercial del Vendedor: registro de solicitudes y gestión de cotizaciones derivadas. | C15: FUNCIONAL | D15: Levantar pedido | E15: Registro de la solicitud que inicia el circuito comercial, incluyendo cliente y documentación. | F15: Como Vendedor quiero registrar una solicitud para iniciar el proceso comercial | G15: Dado que se referencia un cliente_id inexistente Cuando se intenta registrar la solicitud Entonces el sistema rechaza la asociación | H15: TC-A-1.1-13 | I15: EP-01 | J15: F-01 | K15: US-1.1 | L15: Registrar solicitud con cliente inexistente | M15: Intentar registrar una solicitud utilizando un cliente_id inexistente. | N15: HIGH | O15: NEGATIVE | P15: Usuario Vendedor autenticado. | Q15: cliente_id inexistente. | R15: No debe asociarse una solicitud a un cliente inexistente. | S15: 1. Referenciar un cliente_id inexistente. 2. Completar descripción y cantidad. 3. Intentar guardar. | T15: El sistema rechaza la asociación y no registra la solicitud con ese cliente. | V15: NOT RUN | X15: Confirmar el mensaje de validación esperado.
A16: Épica 1 — Vendedor | B16: Circuito comercial del Vendedor: registro de solicitudes y gestión de cotizaciones derivadas. | C16: FUNCIONAL | D16: Levantar pedido | E16: Registro de la solicitud que inicia el circuito comercial, incluyendo cliente y documentación. | F16: Como Vendedor quiero registrar una solicitud para iniciar el proceso comercial | G16: Dado que el Vendedor adjunta documentación válida Cuando guarda la solicitud Entonces el archivo queda asociado a la solicitud | H16: TC-A-1.1-14 | I16: EP-01 | J16: F-01 | K16: US-1.1 | L16: Registrar solicitud con documentación válida | M16: Registrar una solicitud adjuntando documentación válida. | N16: MEDIUM | O16: FUNCTIONAL | P16: Usuario Vendedor autenticado. | Q16: Archivo de documentación válido según reglas del sistema. | R16: La documentación válida puede asociarse a la solicitud. | S16: 1. Completar los datos obligatorios. 2. Adjuntar la documentación válida. 3. Guardar la solicitud. 4. Consultar la solicitud y verificar el adjunto. | T16: La solicitud se registra y la documentación queda asociada correctamente. | V16: NOT RUN | X16: Confirmar formatos permitidos y tamaño máximo según implementación.
A17: Épica 1 — Vendedor | B17: Circuito comercial del Vendedor: registro de solicitudes y gestión de cotizaciones derivadas. | C17: FUNCIONAL | D17: Levantar pedido | E17: Registro de la solicitud que inicia el circuito comercial, incluyendo cliente y documentación. | F17: Como Vendedor quiero registrar una solicitud para iniciar el proceso comercial | G17: Dado que el Vendedor intenta adjuntar un archivo no permitido Cuando guarda la solicitud Entonces el archivo no debe aceptarse | H17: TC-A-1.1-15 | I17: EP-01 | J17: F-01 | K17: US-1.1 | L17: Registrar solicitud con archivo no permitido | M17: Intentar adjuntar un archivo que no cumpla las reglas permitidas. | N17: MEDIUM | O17: NEGATIVE | P17: Usuario Vendedor autenticado. | Q17: Archivo no permitido. | R17: El archivo no permitido no debe ser aceptado. | S17: 1. Completar los datos obligatorios. 2. Intentar adjuntar un archivo no permitido. 3. Intentar guardar. | T17: El sistema rechaza el archivo y evita asociarlo a la solicitud. | V17: NOT RUN
A18: Épica 1 — Vendedor | B18: Circuito comercial del Vendedor: registro de solicitudes y gestión de cotizaciones derivadas. | C18: FUNCIONAL | D18: Levantar pedido | E18: Registro de la solicitud que inicia el circuito comercial, incluyendo cliente y documentación. | F18: Como Vendedor quiero registrar una solicitud para iniciar el proceso comercial | G18: Dado que el Vendedor no adjunta documentación Cuando guarda la solicitud con el resto de los datos válidos Entonces la solicitud se registra sin adjuntos | H18: TC-A-1.1-16 | I18: EP-01 | J18: F-01 | K18: US-1.1 | L18: Registrar solicitud sin documentación | M18: Registrar una solicitud sin adjuntar documentación. | N18: MEDIUM | O18: FUNCTIONAL | P18: Usuario Vendedor autenticado. | Q18: Sin archivo adjunto; demás datos válidos. | R18: Verificar comportamiento cuando no se adjunta documentación. | S18: 1. Completar los datos obligatorios. 2. No adjuntar ningún archivo. 3. Guardar la solicitud. | T18: La solicitud se registra si la documentación no es obligatoria. | V18: NOT RUN | X18: Confirmar si el adjunto es obligatorio; si lo fuera, este caso pasa a NEGATIVE.
A19: Épica 5 — Gerente | B19: Configuración global del catálogo de fases y de los operarios elegibles para ejecutarlas. | C19: FUNCIONAL | D19: Configuración global de fases | E19: Catálogo global de fases y elegibilidad de operarios por fase. | F19: Como Gerente quiero configurar el catálogo global de fases y sus operarios elegibles para que la OT asigne correctamente la primera fase | G19: Dado que el Gerente está autenticado Cuando accede al catálogo global de fases Entonces puede consultar las fases configuradas | H19: TC-A-5.1-01 | I19: EP-05 | J19: F-02 | K19: US-5.1 | L19: Consultar catálogo de fases | M19: El Gerente consulta el catálogo global de fases. | N19: HIGH | O19: FUNCTIONAL | P19: Usuario Gerente autenticado. | Q19: Catálogo existente. | R19: El Gerente puede consultar las fases configuradas. | S19: 1. Ingresar como Gerente. 2. Acceder al catálogo de fases. | T19: Se muestra el catálogo disponible. | V19: NOT RUN
A20: Épica 5 — Gerente | B20: Configuración global del catálogo de fases y de los operarios elegibles para ejecutarlas. | C20: FUNCIONAL | D20: Configuración global de fases | E20: Catálogo global de fases y elegibilidad de operarios por fase. | F20: Como Gerente quiero configurar el catálogo global de fases y sus operarios elegibles para que la OT asigne correctamente la primera fase | G20: Dado que el Gerente accede al catálogo Cuando configura una fase y guarda Entonces la configuración queda registrada | H20: TC-A-5.1-02 | I20: EP-05 | J20: F-02 | K20: US-5.1 | L20: Configurar fase | M20: El Gerente configura una fase del catálogo. | N20: HIGH | O20: FUNCTIONAL | P20: Usuario Gerente autenticado. | Q20: Fase válida. | R20: El Gerente puede configurar una fase. | S20: 1. Acceder al catálogo. 2. Seleccionar una fase. 3. Configurar los datos correspondientes. 4. Guardar. | T20: La configuración se guarda correctamente. | V20: NOT RUN
A21: Épica 5 — Gerente | B21: Configuración global del catálogo de fases y de los operarios elegibles para ejecutarlas. | C21: FUNCIONAL | D21: Configuración global de fases | E21: Catálogo global de fases y elegibilidad de operarios por fase. | F21: Como Gerente quiero configurar el catálogo global de fases y sus operarios elegibles para que la OT asigne correctamente la primera fase | G21: Dado que existe una fase configurada y operarios disponibles Cuando el Gerente define los operarios elegibles y guarda Entonces la fase queda asociada a esos operarios | H21: TC-A-5.1-03 | I21: EP-05 | J21: F-02 | K21: US-5.1 | L21: Configurar operarios elegibles para una fase | M21: El Gerente define qué operarios pueden ejecutar una fase. | N21: HIGH | O21: FUNCTIONAL | P21: Usuario Gerente autenticado; fase configurada. | Q21: Fase + operario/s elegibles. | R21: La configuración de elegibilidad queda registrada. | S21: 1. Seleccionar una fase. 2. Consultar los operarios disponibles. 3. Definir los operarios elegibles. 4. Guardar. | T21: La fase queda asociada a los operarios seleccionados. | V21: NOT RUN
A22: Épica 5 — Gerente | B22: Configuración global del catálogo de fases y de los operarios elegibles para ejecutarlas. | C22: FUNCIONAL | D22: Configuración global de fases | E22: Catálogo global de fases y elegibilidad de operarios por fase. | F22: Como Gerente quiero configurar el catálogo global de fases y sus operarios elegibles para que la OT asigne correctamente la primera fase | G22: Dado que la fase tiene operarios elegibles configurados Cuando se consultan los ejecutores posibles Entonces el operario habilitado aparece como elegible | H22: TC-A-5.1-04 | I22: EP-05 | J22: F-02 | K22: US-5.1 | L22: Verificar operario habilitado para una fase | M22: Verificar que un operario configurado como elegible pueda recibir la fase correspondiente. | N22: HIGH | O22: INTEGRATION | P22: Fase configurada; operario habilitado. | Q22: Fase + operario habilitado. | R22: Un operario habilitado puede recibir la fase. | S22: 1. Seleccionar la fase. 2. Consultar los operarios elegibles. 3. Verificar la presencia del operario habilitado. | T22: El operario habilitado aparece como elegible para la fase. | V22: NOT RUN
A23: Épica 5 — Gerente | B23: Configuración global del catálogo de fases y de los operarios elegibles para ejecutarlas. | C23: FUNCIONAL | D23: Configuración global de fases | E23: Catálogo global de fases y elegibilidad de operarios por fase. | F23: Como Gerente quiero configurar el catálogo global de fases y sus operarios elegibles para que la OT asigne correctamente la primera fase | G23: Dado que la fase tiene definidos sus operarios elegibles Cuando se consulta un operario no habilitado Entonces no debe figurar como elegible para esa fase | H23: TC-A-5.1-05 | I23: EP-05 | J23: F-02 | K23: US-5.1 | L23: Verificar operario no habilitado para una fase | M23: Verificar que un operario no configurado como elegible no pueda recibir la fase. | N23: HIGH | O23: NEGATIVE | P23: Fase configurada; operario no habilitado. | Q23: Fase + operario no habilitado. | R23: Un operario no habilitado no debe resultar elegible. | S23: 1. Consultar la configuración de la fase. 2. Identificar un operario no habilitado. 3. Verificar su elegibilidad para la fase. | T23: El operario no habilitado no aparece como elegible para esa fase. | V23: NOT RUN
A24: Épica 5 — Gerente | B24: Configuración global del catálogo de fases y de los operarios elegibles para ejecutarlas. | C24: FUNCIONAL | D24: Configuración global de fases | E24: Catálogo global de fases y elegibilidad de operarios por fase. | F24: Como Gerente quiero configurar el catálogo global de fases y sus operarios elegibles para que la OT asigne correctamente la primera fase | G24: Dado que el catálogo está configurado Cuando el Jefe accede a la consulta del catálogo Entonces puede ver las fases disponibles para seleccionar | H24: TC-A-5.1-06 | I24: EP-05 | J24: F-02 | K24: US-5.1 | L24: Jefe consulta catálogo de fases | M24: El Jefe de producción consulta las fases disponibles para una cotización. | N24: HIGH | O24: FUNCTIONAL | P24: Usuario Jefe de producción autenticado; catálogo configurado. | Q24: Catálogo de fases. | R24: El Jefe puede consultar el catálogo. | S24: 1. Ingresar como Jefe de producción. 2. Acceder a la consulta del catálogo de fases. | T24: Se muestran las fases disponibles para seleccionar. | V24: NOT RUN
A25: Épica 2 — Jefe de Producción | B25: Recepción de la solicitud y armado de la cotización con las fases que componen la futura OT. | C25: FUNCIONAL | D25: Recepción de cotización | E25: Selección de fases, orden, repetición, tiempos estimados, precio final y generación de la cotización. | F25: Como Jefe de Producción quiero recibir la solicitud y preparar la cotización con las fases necesarias para definir la futura OT | G25: Dado que existe una solicitud en PENDIENTE_COTIZACION Cuando el Jefe la consulta Entonces puede ver los datos necesarios para cotizar | H25: TC-A-2.1-01 | I25: EP-02 | J25: F-03 | K25: US-2.1 | L25: Consultar solicitud para cotizar | M25: El Jefe consulta una solicitud pendiente de cotización. | N25: HIGH | O25: FUNCTIONAL | P25: Solicitud en PENDIENTE_COTIZACION. | Q25: Solicitud válida. | R25: El Jefe puede consultar la solicitud. | S25: 1. Ingresar como Jefe. 2. Consultar las solicitudes pendientes de cotización. 3. Seleccionar la solicitud. | T25: Se muestran los datos necesarios para preparar la cotización. | U25: PASS | V25: PASS
A26: Épica 2 — Jefe de Producción | B26: Recepción de la solicitud y armado de la cotización con las fases que componen la futura OT. | C26: FUNCIONAL | D26: Recepción de cotización | E26: Selección de fases, orden, repetición, tiempos estimados, precio final y generación de la cotización. | F26: Como Jefe de Producción quiero recibir la solicitud y preparar la cotización con las fases necesarias para definir la futura OT | G26: Dado que el Jefe abrió una solicitud a cotizar Cuando selecciona las fases necesarias Entonces quedan asociadas a la cotización | H26: TC-A-2.1-02 | I26: EP-02 | J26: F-03 | K26: US-2.1 | L26: Seleccionar fases | M26: Seleccionar las fases necesarias para ejecutar el trabajo. | N26: HIGH | O26: FUNCTIONAL | P26: Solicitud disponible; fases configuradas. | Q26: Una o más fases. | R26: Las fases seleccionadas quedan asociadas a la cotización. | S26: 1. Abrir la solicitud. 2. Consultar el catálogo de fases. 3. Seleccionar las fases necesarias. | T26: Las fases seleccionadas se registran correctamente. | U26: PASS | V26: PASS
A27: Épica 2 — Jefe de Producción | B27: Recepción de la solicitud y armado de la cotización con las fases que componen la futura OT. | C27: FUNCIONAL | D27: Recepción de cotización | E27: Selección de fases, orden, repetición, tiempos estimados, precio final y generación de la cotización. | F27: Como Jefe de Producción quiero recibir la solicitud y preparar la cotización con las fases necesarias para definir la futura OT | G27: Dado que la cotización tiene varias fases seleccionadas Cuando el Jefe define el orden de ejecución y guarda Entonces las fases quedan en ese orden | H27: TC-A-2.1-03 | I27: EP-02 | J27: F-03 | K27: US-2.1 | L27: Definir orden de fases | M27: Establecer el orden de ejecución de las fases. | N27: HIGH | O27: FUNCTIONAL | P27: Fases seleccionadas. | Q27: Orden válido. | R27: El Jefe puede definir el orden de las fases. | S27: 1. Seleccionar varias fases. 2. Definir el orden de ejecución. 3. Guardar. | T27: El orden queda registrado correctamente. | U27: PASS | V27: PASS
A28: Épica 2 — Jefe de Producción | B28: Recepción de la solicitud y armado de la cotización con las fases que componen la futura OT. | C28: FUNCIONAL | D28: Recepción de cotización | E28: Selección de fases, orden, repetición, tiempos estimados, precio final y generación de la cotización. | F28: Como Jefe de Producción quiero recibir la solicitud y preparar la cotización con las fases necesarias para definir la futura OT | G28: Dado que una fase puede repetirse dentro del circuito Cuando el Jefe la incorpora más de una vez Entonces la secuencia admite la repetición | H28: TC-A-2.1-04 | I28: EP-02 | J28: F-03 | K28: US-2.1 | L28: Repetir una fase | M28: Incluir una misma fase más de una vez en la secuencia. | N28: HIGH | O28: VALIDATION | P28: Fase disponible. | Q28: Fase repetida. | R28: El mismo tipo de fase puede repetirse. | S28: 1. Seleccionar una fase. 2. Incorporar nuevamente la misma fase. 3. Definir el orden. 4. Guardar. | T28: El sistema permite registrar la repetición de la fase. | U28: PASS | V28: PASS
A29: Épica 2 — Jefe de Producción | B29: Recepción de la solicitud y armado de la cotización con las fases que componen la futura OT. | C29: FUNCIONAL | D29: Recepción de cotización | E29: Selección de fases, orden, repetición, tiempos estimados, precio final y generación de la cotización. | F29: Como Jefe de Producción quiero recibir la solicitud y preparar la cotización con las fases necesarias para definir la futura OT | G29: Dado que la cotización tiene fases seleccionadas Cuando el Jefe informa el tiempo estimado de cada fase Entonces cada fase queda asociada a su tiempo | H29: TC-A-2.1-05 | I29: EP-02 | J29: F-03 | K29: US-2.1 | L29: Definir tiempo estimado por fase | M29: Registrar el tiempo estimado para cada fase. | N29: HIGH | O29: FUNCTIONAL | P29: Fases seleccionadas. | Q29: Tiempo estimado por fase. | R29: Cada fase debe tener su tiempo estimado. | S29: 1. Seleccionar las fases. 2. Informar el tiempo estimado de cada fase. 3. Guardar. | T29: El tiempo estimado queda asociado a cada fase. | U29: PASS | V29: PASS
A30: Épica 2 — Jefe de Producción | B30: Recepción de la solicitud y armado de la cotización con las fases que componen la futura OT. | C30: FUNCIONAL | D30: Recepción de cotización | E30: Selección de fases, orden, repetición, tiempos estimados, precio final y generación de la cotización. | F30: Como Jefe de Producción quiero recibir la solicitud y preparar la cotización con las fases necesarias para definir la futura OT | G30: Dado que la cotización tiene sus fases configuradas Cuando el Jefe informa el precio final Entonces la cotización mantiene un único precio final | H30: TC-A-2.1-06 | I30: EP-02 | J30: F-03 | K30: US-2.1 | L30: Definir precio final de cotización | M30: Registrar el precio final de la cotización. | N30: HIGH | O30: FUNCTIONAL | P30: Cotización con fases configuradas. | Q30: Precio final válido. | R30: La cotización utiliza un único precio final. | S30: 1. Configurar las fases. 2. Informar el precio final. 3. Guardar. | T30: El precio final queda registrado correctamente. | U30: PASS | V30: PASS
A31: Épica 2 — Jefe de Producción | B31: Recepción de la solicitud y armado de la cotización con las fases que componen la futura OT. | C31: FUNCIONAL | D31: Recepción de cotización | E31: Selección de fases, orden, repetición, tiempos estimados, precio final y generación de la cotización. | F31: Como Jefe de Producción quiero recibir la solicitud y preparar la cotización con las fases necesarias para definir la futura OT | G31: Dado que la cotización está completa Cuando el Jefe la genera Entonces queda registrada y asociada a la solicitud | H31: TC-A-2.1-07 | I31: EP-02 | J31: F-03 | K31: US-2.1 | L31: Generar cotización | M31: Generar la cotización a partir de la solicitud y configuración de fases. | N31: HIGH | O31: INTEGRATION | P31: Solicitud válida; fases y tiempos definidos; precio final definido. | Q31: Datos completos de cotización. | R31: La cotización puede generarse correctamente. | S31: 1. Completar la configuración de la cotización. 2. Generar la cotización. 3. Consultar la cotización generada. | T31: Se genera la cotización con la información configurada. | U31: PASS | V31: PASS
A32: Épica 2 — Jefe de Producción | B32: Recepción de la solicitud y armado de la cotización con las fases que componen la futura OT. | C32: FUNCIONAL | D32: Recepción de cotización | E32: Selección de fases, orden, repetición, tiempos estimados, precio final y generación de la cotización. | F32: Como Jefe de Producción quiero recibir la solicitud y preparar la cotización con las fases necesarias para definir la futura OT | G32: Dado que la cotización fue generada Cuando se consulta su estado Entonces corresponde al definido en el flujo comercial | H32: TC-A-2.1-08 | I32: EP-02 | J32: F-03 | K32: US-2.1 | L32: Verificar estado de la cotización | M32: Verificar el estado de la cotización luego de su generación. | N32: HIGH | O32: VALIDATION | P32: Cotización generada. | Q32: Cotización válida. | R32: El estado debe corresponder al flujo definido. | S32: 1. Generar la cotización. 2. Consultar el estado de la cotización. | T32: La cotización queda disponible para ser enviada al cliente. | U32: PASS | V32: PASS
A33: Épica 1 — Vendedor | B33: Circuito comercial del Vendedor: registro de solicitudes y gestión de cotizaciones derivadas. | C33: FUNCIONAL | D33: Cotizaciones derivadas | E33: Consulta de la cotización, envío al cliente y registro de la decisión del cliente. | F33: Como Vendedor quiero consultar la cotización derivada, enviarla al cliente y registrar su decisión para continuar o cerrar el circuito comercial | G33: Dado que existe una cotización generada Cuando el Vendedor la consulta Entonces puede acceder a la cotización | H33: TC-A-1.3-01 | I33: EP-01 | J33: F-04 | K33: US-1.3 | L33: Consultar cotización | M33: El Vendedor consulta una cotización generada. | N33: HIGH | O33: FUNCTIONAL | P33: Cotización generada. | Q33: Cotización válida. | R33: El Vendedor puede consultar la cotización. | S33: 1. Ingresar como Vendedor. 2. Consultar las cotizaciones disponibles. 3. Seleccionar la cotización. | T33: La cotización se muestra correctamente. | U33: PASS | V33: PASS
A34: Épica 1 — Vendedor | B34: Circuito comercial del Vendedor: registro de solicitudes y gestión de cotizaciones derivadas. | C34: FUNCIONAL | D34: Cotizaciones derivadas | E34: Consulta de la cotización, envío al cliente y registro de la decisión del cliente. | F34: Como Vendedor quiero consultar la cotización derivada, enviarla al cliente y registrar su decisión para continuar o cerrar el circuito comercial | G34: Dado que la cotización tiene datos completos Cuando el Vendedor la abre Entonces visualiza fases, tiempos y precio final consistentes | H34: TC-A-1.3-02 | I34: EP-01 | J34: F-04 | K34: US-1.3 | L34: Visualizar datos de cotización | M34: Verificar que la cotización muestre sus datos principales. | N34: HIGH | O34: VALIDATION | P34: Cotización disponible. | Q34: Cotización con fases, tiempos y precio final. | R34: Los datos deben corresponder a la cotización generada. | S34: 1. Abrir la cotización. 2. Revisar cliente, solicitud, fases, tiempos y precio final. | T34: Se muestran correctamente los datos de la cotización. | U34: PASS | V34: PASS
A35: Épica 1 — Vendedor | B35: Circuito comercial del Vendedor: registro de solicitudes y gestión de cotizaciones derivadas. | C35: FUNCIONAL | D35: Cotizaciones derivadas | E35: Consulta de la cotización, envío al cliente y registro de la decisión del cliente. | F35: Como Vendedor quiero consultar la cotización derivada, enviarla al cliente y registrar su decisión para continuar o cerrar el circuito comercial | G35: Dado que la cotización está en ENVIADA_A_CLIENTE Cuando el Vendedor registra la aprobación Entonces la aprobación queda registrada | H35: TC-A-1.3-03 | I35: EP-01 | J35: F-04 | K35: US-1.3 | L35: Aprobar cotización | M35: El Vendedor registra la aprobación de una cotización enviada. | N35: CRITICAL | O35: FUNCTIONAL | P35: Cotización en ENVIADA_A_CLIENTE. | Q35: Cotización enviada. | R35: El Vendedor puede aprobar la cotización. | S35: 1. Abrir la cotización enviada. 2. Seleccionar la aprobación. 3. Confirmar la acción. | T35: La aprobación se registra correctamente. | U35: FAIL | V35: FAIL
A36: Épica 1 — Vendedor | B36: Circuito comercial del Vendedor: registro de solicitudes y gestión de cotizaciones derivadas. | C36: FUNCIONAL | D36: Cotizaciones derivadas | E36: Consulta de la cotización, envío al cliente y registro de la decisión del cliente. | F36: Como Vendedor quiero consultar la cotización derivada, enviarla al cliente y registrar su decisión para continuar o cerrar el circuito comercial | G36: Dado que la aprobación fue registrada Cuando se consulta el estado Entonces la cotización figura en APROBADA | H36: TC-A-1.3-04 | I36: EP-01 | J36: F-04 | K36: US-1.3 | L36: Verificar estado APROBADA | M36: Verificar el estado luego de la aprobación. | N36: CRITICAL | O36: VALIDATION | P36: Cotización aprobada. | Q36: Cotización válida. | R36: La cotización aprobada debe quedar en APROBADA. | S36: 1. Registrar la aprobación. 2. Consultar el estado de la cotización. | T36: El estado cambia a APROBADA. | U36: BLOCKED | V36: BLOCKED
... A39: Épica 1 — Vendedor | B39: Circuito comercial del Vendedor: registro de solicitudes y gestión de cotizaciones derivadas. | C39: FUNCIONAL | D39: Cotizaciones derivadas | E39: Consulta de la cotización, envío al cliente y registro de la decisión del cliente. | F39: Como Vendedor quiero consultar la cotización derivada, enviarla al cliente y registrar su decisión para continuar o cerrar el circuito comercial | G39: Dado que la OT fue generada con sus fases Cuando se consultan las fases de la OT Entonces la primera figura en EN_COLA | H39: TC-A-1.3-07 | I39: EP-01 | J39: F-04 | K39: US-1.3 | L39: Verificar primera fase en cola | M39: Verificar el estado de la primera fase de la OT. | N39: CRITICAL | O39: INTEGRATION | P39: OT generada; fases configuradas. | Q39: OT con secuencia de fases. | R39: La primera fase debe quedar en EN_COLA. | S39: 1. Consultar la OT generada. 2. Consultar la secuencia de fases. 3. Verificar el estado de la primera fase. | T39: La primera fase queda disponible en estado EN_COLA. | U39: BLOCKED | V39: BLOCKED
A40: Épica 1 — Vendedor | B40: Circuito comercial del Vendedor: registro de solicitudes y gestión de cotizaciones derivadas. | C40: FUNCIONAL | D40: Cotizaciones derivadas | E40: Consulta de la cotización, envío al cliente y registro de la decisión del cliente. | F40: Como Vendedor quiero consultar la cotización derivada, enviarla al cliente y registrar su decisión para continuar o cerrar el circuito comercial | G40: Dado que la OT fue generada y la fase tiene operarios elegibles Cuando se consulta la primera fase Entonces aparece disponible para el operario elegible correspondiente | H40: TC-A-1.3-08 | I40: EP-01 | J40: F-04 | K40: US-1.3 | L40: Verificar primer operario correcto | M40: Verificar que la primera fase quede visible para un operario elegible. | N40: CRITICAL | O40: E2E | P40: OT generada; configuración de HU-5.1 disponible. | Q40: Fase + operario elegible. | R40: La primera fase debe quedar disponible para un operario habilitado. | S40: 1. Consultar la primera fase de la OT. 2. Verificar el operario al que queda disponible. | T40: La fase aparece para el operario correspondiente. | V40: NOT RUN | X40: Dependencia funcional de HU-5.1.
A41: Épica 1 — Vendedor | B41: Circuito comercial del Vendedor: registro de solicitudes y gestión de cotizaciones derivadas. | C41: FUNCIONAL | D41: Cotizaciones derivadas | E41: Consulta de la cotización, envío al cliente y registro de la decisión del cliente. | F41: Como Vendedor quiero consultar la cotización derivada, enviarla al cliente y registrar su decisión para continuar o cerrar el circuito comercial | G41: Dado que la cotización está en ENVIADA_A_CLIENTE Cuando el Vendedor registra la no aprobación Entonces la decisión queda registrada | H41: TC-A-1.3-09 | I41: EP-01 | J41: F-04 | K41: US-1.3 | L41: No aprobar cotización | M41: El Vendedor registra que no aprueba una cotización enviada. | N41: HIGH | O41: FUNCTIONAL | P41: Cotización en ENVIADA_A_CLIENTE. | Q41: Cotización enviada. | R41: El Vendedor puede registrar la no aprobación. | S41: 1. Abrir la cotización enviada. 2. Seleccionar la no aprobación. 3. Confirmar la acción. | T41: La no aprobación se registra correctamente. | V41: NOT RUN
A42: Épica 1 — Vendedor | B42: Circuito comercial del Vendedor: registro de solicitudes y gestión de cotizaciones derivadas. | C42: FUNCIONAL | D42: Cotizaciones derivadas | E42: Consulta de la cotización, envío al cliente y registro de la decisión del cliente. | F42: Como Vendedor quiero consultar la cotización derivada, enviarla al cliente y registrar su decisión para continuar o cerrar el circuito comercial | G42: Dado que la no aprobación fue registrada Cuando se consulta el estado Entonces la cotización figura en NO_APROBADA | H42: TC-A-1.3-10 | I42: EP-01 | J42: F-04 | K42: US-1.3 | L42: Verificar estado NO_APROBADA | M42: Verificar el estado luego de registrar la no aprobación. | N42: HIGH | O42: VALIDATION | P42: Cotización no aprobada. | Q42: Cotización válida. | R42: La cotización debe quedar en NO_APROBADA. | S42: 1. Registrar la no aprobación. 2. Consultar el estado de la cotización. | T42: El estado cambia a NO_APROBADA. | V42: NOT RUN
...

Sheet LISTAS
A1: PRIORITY | B1: TYPE | C1: STATUS | D1: SEVERITY | E1: REQUERIMIENTO
A2: CRITICAL | B2: FUNCTIONAL | C2: NOT RUN | D2: CRITICAL | E2: FUNCIONAL
A3: HIGH | B3: NEGATIVE | C3: PASS | D3: HIGH | E3: NO FUNCIONAL
A4: MEDIUM | B4: VALIDATION | C4: FAIL | D4: MEDIUM
A5: LOW | B5: INTEGRATION | C5: BLOCKED | D5: LOW
B6: E2E
B7: REGRESSION
B8: SECURITY
A11: Valores controlados. Las columnas REQUERIMIENTO, Priority, Type, Status y Severity de la hoja TEST-CASE tienen listas desplegables con estos valores. SEVERITY se completa únicamente cuando existe un defecto asociado (Defect ID). NOT RUN = caso diseñado sin ejecutar · BLOCKED = dependencia que impide ejecutar · PASS = ejecución satisfactoria · FAIL = resultado no esperado.

Sheet RESUMEN
A1: QualityTrack — Cobertura y ejecución · Fase A (v1.1)
A3: Cobertura por área | B3: Casos | C3: NOT RUN | D3: PASS | E3: FAIL | F3: BLOCKED
A4: HU-1.1 — Levantar pedido | B4: =COUNTIF('TEST-CASE'!$H$3:$H$52,"TC-A-1.1-*") -> 16 | C4: =COUNTIFS('TEST-CASE'!$H$3:$H$52,"TC-A-1.1-*",'TEST-CASE'!$V$3:$V$52,"NOT RUN") -> 13 | D4: =COUNTIFS('TEST-CASE'!$H$3:$H$52,"TC-A-1.1-*",'TEST-CASE'!$V$3:$V$52,"PASS") -> 2 | E4: =COUNTIFS('TEST-CASE'!$H$3:$H$52,"TC-A-1.1-*",'TEST-CASE'!$V$3:$V$52,"FAIL") -> 1 | F4: =COUNTIFS('TEST-CASE'!$H$3:$H$52,"TC-A-1.1-*",'TEST-CASE'!$V$3:$V$52,"BLOCKED") -> 0
A5: HU-5.1 — Configuración global de fases | B5: =COUNTIF('TEST-CASE'!$H$3:$H$52,"TC-A-5.1-*") -> 6 | C5: =COUNTIFS('TEST-CASE'!$H$3:$H$52,"TC-A-5.1-*",'TEST-CASE'!$V$3:$V$52,"NOT RUN") -> 6 | D5: =COUNTIFS('TEST-CASE'!$H$3:$H$52,"TC-A-5.1-*",'TEST-CASE'!$V$3:$V$52,"PASS") -> 0 | E5: =COUNTIFS('TEST-CASE'!$H$3:$H$52,"TC-A-5.1-*",'TEST-CASE'!$V$3:$V$52,"FAIL") -> 0 | F5: =COUNTIFS('TEST-CASE'!$H$3:$H$52,"TC-A-5.1-*",'TEST-CASE'!$V$3:$V$52,"BLOCKED") -> 0
A6: HU-2.1 — Recepción de cotización | B6: =COUNTIF('TEST-CASE'!$H$3:$H$52,"TC-A-2.1-*") -> 8 | C6: =COUNTIFS('TEST-CASE'!$H$3:$H$52,"TC-A-2.1-*",'TEST-CASE'!$V$3:$V$52,"NOT RUN") -> 0 | D6: =COUNTIFS('TEST-CASE'!$H$3:$H$52,"TC-A-2.1-*",'TEST-CASE'!$V$3:$V$52,"PASS") -> 8 | E6: =COUNTIFS('TEST-CASE'!$H$3:$H$52,"TC-A-2.1-*",'TEST-CASE'!$V$3:$V$52,"FAIL") -> 0 | F6: =COUNTIFS('TEST-CASE'!$H$3:$H$52,"TC-A-2.1-*",'TEST-CASE'!$V$3:$V$52,"BLOCKED") -> 0
A7: HU-1.3 — Cotizaciones derivadas | B7: =COUNTIF('TEST-CASE'!$H$3:$H$52,"TC-A-1.3-*") -> 14 | C7: =COUNTIFS('TEST-CASE'!$H$3:$H$52,"TC-A-1.3-*",'TEST-CASE'!$V$3:$V$52,"NOT RUN") -> 7 | D7: =COUNTIFS('TEST-CASE'!$H$3:$H$52,"TC-A-1.3-*",'TEST-CASE'!$V$3:$V$52,"PASS") -> 2 | E7: =COUNTIFS('TEST-CASE'!$H$3:$H$52,"TC-A-1.3-*",'TEST-CASE'!$V$3:$V$52,"FAIL") -> 1 | F7: =COUNTIFS('TEST-CASE'!$H$3:$H$52,"TC-A-1.3-*",'TEST-CASE'!$V$3:$V$52,"BLOCKED") -> 4
A8: E2E principal | B8: =COUNTIF('TEST-CASE'!$H$3:$H$52,"TC-A-E2E-01") -> 1 | C8: =COUNTIFS('TEST-CASE'!$H$3:$H$52,"TC-A-E2E-01",'TEST-CASE'!$V$3:$V$52,"NOT RUN") -> 1 | D8: =COUNTIFS('TEST-CASE'!$H$3:$H$52,"TC-A-E2E-01",'TEST-CASE'!$V$3:$V$52,"PASS") -> 0 | E8: =COUNTIFS('TEST-CASE'!$H$3:$H$52,"TC-A-E2E-01",'TEST-CASE'!$V$3:$V$52,"FAIL") -> 0 | F8: =COUNTIFS('TEST-CASE'!$H$3:$H$52,"TC-A-E2E-01",'TEST-CASE'!$V$3:$V$52,"BLOCKED") -> 0
A9: E2E negativos | B9: =COUNTIF('TEST-CASE'!$H$3:$H$52,"TC-A-E2E-NEG-*") -> 5 | C9: =COUNTIFS('TEST-CASE'!$H$3:$H$52,"TC-A-E2E-NEG-*",'TEST-CASE'!$V$3:$V$52,"NOT RUN") -> 5 | D9: =COUNTIFS('TEST-CASE'!$H$3:$H$52,"TC-A-E2E-NEG-*",'TEST-CASE'!$V$3:$V$52,"PASS") -> 0 | E9: =COUNTIFS('TEST-CASE'!$H$3:$H$52,"TC-A-E2E-NEG-*",'TEST-CASE'!$V$3:$V$52,"FAIL") -> 0 | F9: =COUNTIFS('TEST-CASE'!$H$3:$H$52,"TC-A-E2E-NEG-*",'TEST-CASE'!$V$3:$V$52,"BLOCKED") -> 0
A10: TOTAL FASE A | B10: =COUNTA('TEST-CASE'!$H$3:$H$52) -> 50 | C10: =COUNTIF('TEST-CASE'!$V$3:$V$52,"NOT RUN") -> 32 | D10: =COUNTIF('TEST-CASE'!$V$3:$V$52,"PASS") -> 12 | E10: =COUNTIF('TEST-CASE'!$V$3:$V$52,"FAIL") -> 2 | F10: =COUNTIF('TEST-CASE'!$V$3:$V$52,"BLOCKED") -> 4
A12: Casos por prioridad | B12: Casos
A13: CRITICAL | B13: =COUNTIF('TEST-CASE'!$N$3:$N$52,"CRITICAL") -> 13
A14: HIGH | B14: =COUNTIF('TEST-CASE'!$N$3:$N$52,"HIGH") -> 31
A15: MEDIUM | B15: =COUNTIF('TEST-CASE'!$N$3:$N$52,"MEDIUM") -> 6
A16: LOW | B16: =COUNTIF('TEST-CASE'!$N$3:$N$52,"LOW") -> 0
A18: Casos por tipo | B18: Casos
A19: FUNCTIONAL | B19: =COUNTIF('TEST-CASE'!$O$3:$O$52,"FUNCTIONAL") -> 20
A20: NEGATIVE | B20: =COUNTIF('TEST-CASE'!$O$3:$O$52,"NEGATIVE") -> 9
A21: VALIDATION | B21: =COUNTIF('TEST-CASE'!$O$3:$O$52,"VALIDATION") -> 8
A22: INTEGRATION | B22: =COUNTIF('TEST-CASE'!$O$3:$O$52,"INTEGRATION") -> 6
A23: E2E | B23: =COUNTIF('TEST-CASE'!$O$3:$O$52,"E2E") -> 7
A24: REGRESSION | B24: =COUNTIF('TEST-CASE'!$O$3:$O$52,"REGRESSION") -> 0
A25: SECURITY | B25: =COUNTIF('TEST-CASE'!$O$3:$O$52,"SECURITY") -> 0
A27: Los conteos se calculan con fórmulas sobre la hoja TEST-CASE (filas 3 a 52) y se actualizan al cambiar Status. Si se agregan casos debajo de la fila 52, extender los rangos.
